[2024-11-10T00:00:01.584+0000] {local_task_job_runner.py:123} INFO - ::group::Pre task execution logs
[2024-11-10T00:00:01.601+0000] {taskinstance.py:2612} INFO - Dependencies all met for dep_context=non-requeueable deps ti=<TaskInstance: spotify_pipeline.repartition scheduled__2024-11-09T00:00:00+00:00 [queued]>
[2024-11-10T00:00:01.610+0000] {taskinstance.py:2612} INFO - Dependencies all met for dep_context=requeueable deps ti=<TaskInstance: spotify_pipeline.repartition scheduled__2024-11-09T00:00:00+00:00 [queued]>
[2024-11-10T00:00:01.611+0000] {taskinstance.py:2865} INFO - Starting attempt 1 of 1
[2024-11-10T00:00:01.624+0000] {taskinstance.py:2888} INFO - Executing <Task(SparkSubmitOperator): repartition> on 2024-11-09 00:00:00+00:00
[2024-11-10T00:00:01.630+0000] {standard_task_runner.py:72} INFO - Started process 9171 to run task
[2024-11-10T00:00:01.636+0000] {standard_task_runner.py:104} INFO - Running: ['***', 'tasks', 'run', 'spotify_pipeline', 'repartition', 'scheduled__2024-11-09T00:00:00+00:00', '--job-id', '53', '--raw', '--subdir', 'DAGS_FOLDER/spotify_pipeline.py', '--cfg-path', '/tmp/tmpax3f97uq']
[2024-11-10T00:00:01.640+0000] {standard_task_runner.py:105} INFO - Job 53: Subtask repartition
[2024-11-10T00:00:01.697+0000] {task_command.py:467} INFO - Running <TaskInstance: spotify_pipeline.repartition scheduled__2024-11-09T00:00:00+00:00 [running]> on host d2265ead819e
[2024-11-10T00:00:01.786+0000] {taskinstance.py:3131} INFO - Exporting env vars: AIRFLOW_CTX_DAG_OWNER='JK' AIRFLOW_CTX_DAG_ID='spotify_pipeline' AIRFLOW_CTX_TASK_ID='repartition' AIRFLOW_CTX_EXECUTION_DATE='2024-11-09T00:00:00+00:00' AIRFLOW_CTX_TRY_NUMBER='1' AIRFLOW_CTX_DAG_RUN_ID='scheduled__2024-11-09T00:00:00+00:00'
[2024-11-10T00:00:01.788+0000] {taskinstance.py:731} INFO - ::endgroup::
[2024-11-10T00:00:01.809+0000] {base.py:84} INFO - Retrieving connection 'spark-conn'
[2024-11-10T00:00:01.810+0000] {spark_submit.py:473} INFO - Spark-Submit cmd: spark-submit --master spark://172.23.0.2:7077 --name arrow-spark --deploy-mode client jobs/python/repartition_countries.py /opt/data/kaggle_spotify.csv 10 /opt/data/bronze/kaggle_spotify
[2024-11-10T00:00:06.137+0000] {spark_submit.py:634} INFO - 24/11/10 00:00:06 INFO SparkContext: Running Spark version 3.4.2
[2024-11-10T00:00:06.230+0000] {spark_submit.py:634} INFO - 24/11/10 00:00:06 WARN NativeCodeLoader: Unable to load native-hadoop library for your platform... using builtin-java classes where applicable
[2024-11-10T00:00:06.383+0000] {spark_submit.py:634} INFO - 24/11/10 00:00:06 INFO ResourceUtils: ==============================================================
[2024-11-10T00:00:06.384+0000] {spark_submit.py:634} INFO - 24/11/10 00:00:06 INFO ResourceUtils: No custom resources configured for spark.driver.
[2024-11-10T00:00:06.386+0000] {spark_submit.py:634} INFO - 24/11/10 00:00:06 INFO ResourceUtils: ==============================================================
[2024-11-10T00:00:06.387+0000] {spark_submit.py:634} INFO - 24/11/10 00:00:06 INFO SparkContext: Submitted application: RepartitionCountries
[2024-11-10T00:00:06.424+0000] {spark_submit.py:634} INFO - 24/11/10 00:00:06 INFO ResourceProfile: Default ResourceProfile created, executor resources: Map(memory -> name: memory, amount: 1024, script: , vendor: , offHeap -> name: offHeap, amount: 0, script: , vendor: ), task resources: Map(cpus -> name: cpus, amount: 1.0)
[2024-11-10T00:00:06.436+0000] {spark_submit.py:634} INFO - 24/11/10 00:00:06 INFO ResourceProfile: Limiting resource is cpu
[2024-11-10T00:00:06.438+0000] {spark_submit.py:634} INFO - 24/11/10 00:00:06 INFO ResourceProfileManager: Added ResourceProfile id: 0
[2024-11-10T00:00:06.504+0000] {spark_submit.py:634} INFO - 24/11/10 00:00:06 INFO SecurityManager: Changing view acls to: root
[2024-11-10T00:00:06.505+0000] {spark_submit.py:634} INFO - 24/11/10 00:00:06 INFO SecurityManager: Changing modify acls to: root
[2024-11-10T00:00:06.507+0000] {spark_submit.py:634} INFO - 24/11/10 00:00:06 INFO SecurityManager: Changing view acls groups to:
[2024-11-10T00:00:06.509+0000] {spark_submit.py:634} INFO - 24/11/10 00:00:06 INFO SecurityManager: Changing modify acls groups to:
[2024-11-10T00:00:06.510+0000] {spark_submit.py:634} INFO - 24/11/10 00:00:06 INFO SecurityManager: SecurityManager: authentication disabled; ui acls disabled; users with view permissions: root; groups with view permissions: EMPTY; users with modify permissions: root; groups with modify permissions: EMPTY
[2024-11-10T00:00:06.945+0000] {spark_submit.py:634} INFO - 24/11/10 00:00:06 INFO Utils: Successfully started service 'sparkDriver' on port 41093.
[2024-11-10T00:00:07.006+0000] {spark_submit.py:634} INFO - 24/11/10 00:00:07 INFO SparkEnv: Registering MapOutputTracker
[2024-11-10T00:00:07.068+0000] {spark_submit.py:634} INFO - 24/11/10 00:00:07 INFO SparkEnv: Registering BlockManagerMaster
[2024-11-10T00:00:07.102+0000] {spark_submit.py:634} INFO - 24/11/10 00:00:07 INFO BlockManagerMasterEndpoint: Using org.apache.spark.storage.DefaultTopologyMapper for getting topology information
[2024-11-10T00:00:07.105+0000] {spark_submit.py:634} INFO - 24/11/10 00:00:07 INFO BlockManagerMasterEndpoint: BlockManagerMasterEndpoint up
[2024-11-10T00:00:07.112+0000] {spark_submit.py:634} INFO - 24/11/10 00:00:07 INFO SparkEnv: Registering BlockManagerMasterHeartbeat
[2024-11-10T00:00:07.148+0000] {spark_submit.py:634} INFO - 24/11/10 00:00:07 INFO DiskBlockManager: Created local directory at /tmp/blockmgr-35c2bfe7-c9c8-47f8-8e32-3c5ac495f36c
[2024-11-10T00:00:07.181+0000] {spark_submit.py:634} INFO - 24/11/10 00:00:07 INFO MemoryStore: MemoryStore started with capacity 434.4 MiB
[2024-11-10T00:00:07.210+0000] {spark_submit.py:634} INFO - 24/11/10 00:00:07 INFO SparkEnv: Registering OutputCommitCoordinator
[2024-11-10T00:00:07.469+0000] {spark_submit.py:634} INFO - 24/11/10 00:00:07 INFO JettyUtils: Start Jetty 0.0.0.0:4040 for SparkUI
[2024-11-10T00:00:07.555+0000] {spark_submit.py:634} INFO - 24/11/10 00:00:07 WARN Utils: Service 'SparkUI' could not bind on port 4040. Attempting port 4041.
[2024-11-10T00:00:07.557+0000] {spark_submit.py:634} INFO - 24/11/10 00:00:07 WARN Utils: Service 'SparkUI' could not bind on port 4041. Attempting port 4042.
[2024-11-10T00:00:07.558+0000] {spark_submit.py:634} INFO - 24/11/10 00:00:07 WARN Utils: Service 'SparkUI' could not bind on port 4042. Attempting port 4043.
[2024-11-10T00:00:07.575+0000] {spark_submit.py:634} INFO - 24/11/10 00:00:07 INFO Utils: Successfully started service 'SparkUI' on port 4043.
[2024-11-10T00:00:07.810+0000] {spark_submit.py:634} INFO - 24/11/10 00:00:07 INFO StandaloneAppClient$ClientEndpoint: Connecting to master spark://172.23.0.2:7077...
[2024-11-10T00:00:07.876+0000] {spark_submit.py:634} INFO - 24/11/10 00:00:07 INFO TransportClientFactory: Successfully created connection to /172.23.0.2:7077 after 39 ms (0 ms spent in bootstraps)
[2024-11-10T00:00:08.022+0000] {spark_submit.py:634} INFO - 24/11/10 00:00:08 INFO StandaloneSchedulerBackend: Connected to Spark cluster with app ID app-20241110000008-0005
[2024-11-10T00:00:08.036+0000] {spark_submit.py:634} INFO - 24/11/10 00:00:08 INFO Utils: Successfully started service 'org.apache.spark.network.netty.NettyBlockTransferService' on port 35997.
[2024-11-10T00:00:08.037+0000] {spark_submit.py:634} INFO - 24/11/10 00:00:08 INFO NettyBlockTransferService: Server created on d2265ead819e:35997
[2024-11-10T00:00:08.040+0000] {spark_submit.py:634} INFO - 24/11/10 00:00:08 INFO BlockManager: Using org.apache.spark.storage.RandomBlockReplicationPolicy for block replication policy
[2024-11-10T00:00:08.051+0000] {spark_submit.py:634} INFO - 24/11/10 00:00:08 INFO BlockManagerMaster: Registering BlockManager BlockManagerId(driver, d2265ead819e, 35997, None)
[2024-11-10T00:00:08.056+0000] {spark_submit.py:634} INFO - 24/11/10 00:00:08 INFO BlockManagerMasterEndpoint: Registering block manager d2265ead819e:35997 with 434.4 MiB RAM, BlockManagerId(driver, d2265ead819e, 35997, None)
[2024-11-10T00:00:08.059+0000] {spark_submit.py:634} INFO - 24/11/10 00:00:08 INFO BlockManagerMaster: Registered BlockManager BlockManagerId(driver, d2265ead819e, 35997, None)
[2024-11-10T00:00:08.061+0000] {spark_submit.py:634} INFO - 24/11/10 00:00:08 INFO BlockManager: Initialized BlockManager: BlockManagerId(driver, d2265ead819e, 35997, None)
[2024-11-10T00:00:08.394+0000] {spark_submit.py:634} INFO - 24/11/10 00:00:08 INFO StandaloneSchedulerBackend: SchedulerBackend is ready for scheduling beginning after reached minRegisteredResourcesRatio: 0.0
[2024-11-10T00:00:08.846+0000] {spark_submit.py:634} INFO - 24/11/10 00:00:08 INFO SharedState: Setting hive.metastore.warehouse.dir ('null') to the value of spark.sql.warehouse.dir.
[2024-11-10T00:00:08.857+0000] {spark_submit.py:634} INFO - 24/11/10 00:00:08 INFO SharedState: Warehouse path is 'file:/opt/***/spark-warehouse'.
[2024-11-10T00:00:09.803+0000] {spark_submit.py:634} INFO - 24/11/10 00:00:09 INFO InMemoryFileIndex: It took 58 ms to list leaf files for 1 paths.
[2024-11-10T00:00:09.894+0000] {spark_submit.py:634} INFO - 24/11/10 00:00:09 INFO InMemoryFileIndex: It took 8 ms to list leaf files for 1 paths.
[2024-11-10T00:00:12.007+0000] {spark_submit.py:634} INFO - 24/11/10 00:00:12 INFO StandaloneAppClient$ClientEndpoint: Executor added: app-20241110000008-0005/0 on worker-20241109175335-172.23.0.5-35065 (172.23.0.5:35065) with 2 core(s)
[2024-11-10T00:00:12.013+0000] {spark_submit.py:634} INFO - 24/11/10 00:00:12 INFO StandaloneSchedulerBackend: Granted executor ID app-20241110000008-0005/0 on hostPort 172.23.0.5:35065 with 2 core(s), 1024.0 MiB RAM
[2024-11-10T00:00:12.068+0000] {spark_submit.py:634} INFO - 24/11/10 00:00:12 INFO StandaloneAppClient$ClientEndpoint: Executor updated: app-20241110000008-0005/0 is now RUNNING
[2024-11-10T00:00:12.186+0000] {spark_submit.py:634} INFO - 24/11/10 00:00:12 INFO FileSourceStrategy: Pushed Filters:
[2024-11-10T00:00:12.188+0000] {spark_submit.py:634} INFO - 24/11/10 00:00:12 INFO FileSourceStrategy: Post-Scan Filters: (length(trim(value#0, None)) > 0)
[2024-11-10T00:00:12.805+0000] {spark_submit.py:634} INFO - 24/11/10 00:00:12 INFO CodeGenerator: Code generated in 252.964812 ms
[2024-11-10T00:00:12.856+0000] {spark_submit.py:634} INFO - 24/11/10 00:00:12 INFO MemoryStore: Block broadcast_0 stored as values in memory (estimated size 199.6 KiB, free 434.2 MiB)
[2024-11-10T00:00:12.905+0000] {spark_submit.py:634} INFO - 24/11/10 00:00:12 INFO MemoryStore: Block broadcast_0_piece0 stored as bytes in memory (estimated size 34.3 KiB, free 434.2 MiB)
[2024-11-10T00:00:12.909+0000] {spark_submit.py:634} INFO - 24/11/10 00:00:12 INFO BlockManagerInfo: Added broadcast_0_piece0 in memory on d2265ead819e:35997 (size: 34.3 KiB, free: 434.4 MiB)
[2024-11-10T00:00:12.914+0000] {spark_submit.py:634} INFO - 24/11/10 00:00:12 INFO SparkContext: Created broadcast 0 from csv at NativeMethodAccessorImpl.java:0
[2024-11-10T00:00:12.925+0000] {spark_submit.py:634} INFO - 24/11/10 00:00:12 INFO FileSourceScanExec: Planning scan with bin packing, max size: 134217728 bytes, open cost is considered as scanning 4194304 bytes.
[2024-11-10T00:00:13.030+0000] {spark_submit.py:634} INFO - 24/11/10 00:00:13 INFO SparkContext: Starting job: csv at NativeMethodAccessorImpl.java:0
[2024-11-10T00:00:13.042+0000] {spark_submit.py:634} INFO - 24/11/10 00:00:13 INFO DAGScheduler: Got job 0 (csv at NativeMethodAccessorImpl.java:0) with 1 output partitions
[2024-11-10T00:00:13.043+0000] {spark_submit.py:634} INFO - 24/11/10 00:00:13 INFO DAGScheduler: Final stage: ResultStage 0 (csv at NativeMethodAccessorImpl.java:0)
[2024-11-10T00:00:13.044+0000] {spark_submit.py:634} INFO - 24/11/10 00:00:13 INFO DAGScheduler: Parents of final stage: List()
[2024-11-10T00:00:13.045+0000] {spark_submit.py:634} INFO - 24/11/10 00:00:13 INFO DAGScheduler: Missing parents: List()
[2024-11-10T00:00:13.048+0000] {spark_submit.py:634} INFO - 24/11/10 00:00:13 INFO DAGScheduler: Submitting ResultStage 0 (MapPartitionsRDD[3] at csv at NativeMethodAccessorImpl.java:0), which has no missing parents
[2024-11-10T00:00:13.098+0000] {spark_submit.py:634} INFO - 24/11/10 00:00:13 INFO MemoryStore: Block broadcast_1 stored as values in memory (estimated size 12.1 KiB, free 434.2 MiB)
[2024-11-10T00:00:13.106+0000] {spark_submit.py:634} INFO - 24/11/10 00:00:13 INFO MemoryStore: Block broadcast_1_piece0 stored as bytes in memory (estimated size 6.0 KiB, free 434.2 MiB)
[2024-11-10T00:00:13.107+0000] {spark_submit.py:634} INFO - 24/11/10 00:00:13 INFO BlockManagerInfo: Added broadcast_1_piece0 in memory on d2265ead819e:35997 (size: 6.0 KiB, free: 434.4 MiB)
[2024-11-10T00:00:13.109+0000] {spark_submit.py:634} INFO - 24/11/10 00:00:13 INFO SparkContext: Created broadcast 1 from broadcast at DAGScheduler.scala:1535
[2024-11-10T00:00:13.128+0000] {spark_submit.py:634} INFO - 24/11/10 00:00:13 INFO DAGScheduler: Submitting 1 missing tasks from ResultStage 0 (MapPartitionsRDD[3] at csv at NativeMethodAccessorImpl.java:0) (first 15 tasks are for partitions Vector(0))
[2024-11-10T00:00:13.129+0000] {spark_submit.py:634} INFO - 24/11/10 00:00:13 INFO TaskSchedulerImpl: Adding task set 0.0 with 1 tasks resource profile 0
[2024-11-10T00:00:14.377+0000] {spark_submit.py:634} INFO - 24/11/10 00:00:14 INFO StandaloneSchedulerBackend$StandaloneDriverEndpoint: Registered executor NettyRpcEndpointRef(spark-client://Executor) (172.23.0.5:33868) with ID 0,  ResourceProfileId 0
[2024-11-10T00:00:14.434+0000] {spark_submit.py:634} INFO - 24/11/10 00:00:14 INFO BlockManagerMasterEndpoint: Registering block manager 172.23.0.5:32883 with 434.4 MiB RAM, BlockManagerId(0, 172.23.0.5, 32883, None)
[2024-11-10T00:00:14.489+0000] {spark_submit.py:634} INFO - 24/11/10 00:00:14 INFO TaskSetManager: Starting task 0.0 in stage 0.0 (TID 0) (172.23.0.5, executor 0, partition 0, PROCESS_LOCAL, 7919 bytes)
[2024-11-10T00:00:14.722+0000] {spark_submit.py:634} INFO - 24/11/10 00:00:14 INFO BlockManagerInfo: Added broadcast_1_piece0 in memory on 172.23.0.5:32883 (size: 6.0 KiB, free: 434.4 MiB)
[2024-11-10T00:00:15.367+0000] {spark_submit.py:634} INFO - 24/11/10 00:00:15 INFO BlockManagerInfo: Added broadcast_0_piece0 in memory on 172.23.0.5:32883 (size: 34.3 KiB, free: 434.4 MiB)
[2024-11-10T00:00:15.544+0000] {spark_submit.py:634} INFO - 24/11/10 00:00:15 INFO TaskSetManager: Finished task 0.0 in stage 0.0 (TID 0) in 1064 ms on 172.23.0.5 (executor 0) (1/1)
[2024-11-10T00:00:15.546+0000] {spark_submit.py:634} INFO - 24/11/10 00:00:15 INFO TaskSchedulerImpl: Removed TaskSet 0.0, whose tasks have all completed, from pool
[2024-11-10T00:00:15.552+0000] {spark_submit.py:634} INFO - 24/11/10 00:00:15 INFO DAGScheduler: ResultStage 0 (csv at NativeMethodAccessorImpl.java:0) finished in 2.491 s
[2024-11-10T00:00:15.554+0000] {spark_submit.py:634} INFO - 24/11/10 00:00:15 INFO DAGScheduler: Job 0 is finished. Cancelling potential speculative or zombie tasks for this job
[2024-11-10T00:00:15.555+0000] {spark_submit.py:634} INFO - 24/11/10 00:00:15 INFO TaskSchedulerImpl: Killing all running tasks in stage 0: Stage finished
[2024-11-10T00:00:15.557+0000] {spark_submit.py:634} INFO - 24/11/10 00:00:15 INFO DAGScheduler: Job 0 finished: csv at NativeMethodAccessorImpl.java:0, took 2.525957 s
[2024-11-10T00:00:15.582+0000] {spark_submit.py:634} INFO - 24/11/10 00:00:15 INFO CodeGenerator: Code generated in 13.726291 ms
[2024-11-10T00:00:15.623+0000] {spark_submit.py:634} INFO - 24/11/10 00:00:15 INFO FileSourceStrategy: Pushed Filters:
[2024-11-10T00:00:15.625+0000] {spark_submit.py:634} INFO - 24/11/10 00:00:15 INFO FileSourceStrategy: Post-Scan Filters:
[2024-11-10T00:00:15.633+0000] {spark_submit.py:634} INFO - 24/11/10 00:00:15 INFO MemoryStore: Block broadcast_2 stored as values in memory (estimated size 199.6 KiB, free 434.0 MiB)
[2024-11-10T00:00:15.648+0000] {spark_submit.py:634} INFO - 24/11/10 00:00:15 INFO MemoryStore: Block broadcast_2_piece0 stored as bytes in memory (estimated size 34.3 KiB, free 433.9 MiB)
[2024-11-10T00:00:15.649+0000] {spark_submit.py:634} INFO - 24/11/10 00:00:15 INFO BlockManagerInfo: Added broadcast_2_piece0 in memory on d2265ead819e:35997 (size: 34.3 KiB, free: 434.3 MiB)
[2024-11-10T00:00:15.651+0000] {spark_submit.py:634} INFO - 24/11/10 00:00:15 INFO SparkContext: Created broadcast 2 from csv at NativeMethodAccessorImpl.java:0
[2024-11-10T00:00:15.652+0000] {spark_submit.py:634} INFO - 24/11/10 00:00:15 INFO FileSourceScanExec: Planning scan with bin packing, max size: 134217728 bytes, open cost is considered as scanning 4194304 bytes.
[2024-11-10T00:00:15.723+0000] {spark_submit.py:634} INFO - 24/11/10 00:00:15 INFO SparkContext: Starting job: csv at NativeMethodAccessorImpl.java:0
[2024-11-10T00:00:15.726+0000] {spark_submit.py:634} INFO - 24/11/10 00:00:15 INFO DAGScheduler: Got job 1 (csv at NativeMethodAccessorImpl.java:0) with 202 output partitions
[2024-11-10T00:00:15.727+0000] {spark_submit.py:634} INFO - 24/11/10 00:00:15 INFO DAGScheduler: Final stage: ResultStage 1 (csv at NativeMethodAccessorImpl.java:0)
[2024-11-10T00:00:15.728+0000] {spark_submit.py:634} INFO - 24/11/10 00:00:15 INFO DAGScheduler: Parents of final stage: List()
[2024-11-10T00:00:15.729+0000] {spark_submit.py:634} INFO - 24/11/10 00:00:15 INFO DAGScheduler: Missing parents: List()
[2024-11-10T00:00:15.730+0000] {spark_submit.py:634} INFO - 24/11/10 00:00:15 INFO DAGScheduler: Submitting ResultStage 1 (MapPartitionsRDD[9] at csv at NativeMethodAccessorImpl.java:0), which has no missing parents
[2024-11-10T00:00:15.768+0000] {spark_submit.py:634} INFO - 24/11/10 00:00:15 INFO MemoryStore: Block broadcast_3 stored as values in memory (estimated size 26.5 KiB, free 433.9 MiB)
[2024-11-10T00:00:15.775+0000] {spark_submit.py:634} INFO - 24/11/10 00:00:15 INFO MemoryStore: Block broadcast_3_piece0 stored as bytes in memory (estimated size 12.4 KiB, free 433.9 MiB)
[2024-11-10T00:00:15.776+0000] {spark_submit.py:634} INFO - 24/11/10 00:00:15 INFO BlockManagerInfo: Added broadcast_3_piece0 in memory on d2265ead819e:35997 (size: 12.4 KiB, free: 434.3 MiB)
[2024-11-10T00:00:15.777+0000] {spark_submit.py:634} INFO - 24/11/10 00:00:15 INFO SparkContext: Created broadcast 3 from broadcast at DAGScheduler.scala:1535
[2024-11-10T00:00:15.780+0000] {spark_submit.py:634} INFO - 24/11/10 00:00:15 INFO DAGScheduler: Submitting 202 missing tasks from ResultStage 1 (MapPartitionsRDD[9] at csv at NativeMethodAccessorImpl.java:0) (first 15 tasks are for partitions Vector(0, 1, 2, 3, 4, 5, 6, 7, 8, 9, 10, 11, 12, 13, 14))
[2024-11-10T00:00:15.781+0000] {spark_submit.py:634} INFO - 24/11/10 00:00:15 INFO TaskSchedulerImpl: Adding task set 1.0 with 202 tasks resource profile 0
[2024-11-10T00:00:15.784+0000] {spark_submit.py:634} INFO - 24/11/10 00:00:15 INFO TaskSetManager: Starting task 0.0 in stage 1.0 (TID 1) (172.23.0.5, executor 0, partition 0, PROCESS_LOCAL, 7919 bytes)
[2024-11-10T00:00:15.786+0000] {spark_submit.py:634} INFO - 24/11/10 00:00:15 INFO TaskSetManager: Starting task 1.0 in stage 1.0 (TID 2) (172.23.0.5, executor 0, partition 1, PROCESS_LOCAL, 7919 bytes)
[2024-11-10T00:00:15.817+0000] {spark_submit.py:634} INFO - 24/11/10 00:00:15 INFO BlockManagerInfo: Removed broadcast_0_piece0 on d2265ead819e:35997 in memory (size: 34.3 KiB, free: 434.3 MiB)
[2024-11-10T00:00:15.826+0000] {spark_submit.py:634} INFO - 24/11/10 00:00:15 INFO BlockManagerInfo: Added broadcast_3_piece0 in memory on 172.23.0.5:32883 (size: 12.4 KiB, free: 434.3 MiB)
[2024-11-10T00:00:15.827+0000] {spark_submit.py:634} INFO - 24/11/10 00:00:15 INFO BlockManagerInfo: Removed broadcast_0_piece0 on 172.23.0.5:32883 in memory (size: 34.3 KiB, free: 434.4 MiB)
[2024-11-10T00:00:16.957+0000] {spark_submit.py:634} INFO - 24/11/10 00:00:16 INFO BlockManagerInfo: Added broadcast_2_piece0 in memory on 172.23.0.5:32883 (size: 34.3 KiB, free: 434.3 MiB)
[2024-11-10T00:00:19.828+0000] {spark_submit.py:634} INFO - 24/11/10 00:00:19 INFO TaskSetManager: Starting task 2.0 in stage 1.0 (TID 3) (172.23.0.5, executor 0, partition 2, PROCESS_LOCAL, 7919 bytes)
[2024-11-10T00:00:19.832+0000] {spark_submit.py:634} INFO - 24/11/10 00:00:19 INFO TaskSetManager: Finished task 0.0 in stage 1.0 (TID 1) in 4048 ms on 172.23.0.5 (executor 0) (1/202)
[2024-11-10T00:00:19.956+0000] {spark_submit.py:634} INFO - 24/11/10 00:00:19 INFO TaskSetManager: Starting task 3.0 in stage 1.0 (TID 4) (172.23.0.5, executor 0, partition 3, PROCESS_LOCAL, 7919 bytes)
[2024-11-10T00:00:19.959+0000] {spark_submit.py:634} INFO - 24/11/10 00:00:19 INFO TaskSetManager: Finished task 1.0 in stage 1.0 (TID 2) in 4174 ms on 172.23.0.5 (executor 0) (2/202)
[2024-11-10T00:00:22.238+0000] {spark_submit.py:634} INFO - 24/11/10 00:00:22 INFO TaskSetManager: Starting task 4.0 in stage 1.0 (TID 5) (172.23.0.5, executor 0, partition 4, PROCESS_LOCAL, 7919 bytes)
[2024-11-10T00:00:22.239+0000] {spark_submit.py:634} INFO - 24/11/10 00:00:22 INFO TaskSetManager: Finished task 2.0 in stage 1.0 (TID 3) in 2410 ms on 172.23.0.5 (executor 0) (3/202)
[2024-11-10T00:00:22.622+0000] {spark_submit.py:634} INFO - 24/11/10 00:00:22 INFO TaskSetManager: Starting task 5.0 in stage 1.0 (TID 6) (172.23.0.5, executor 0, partition 5, PROCESS_LOCAL, 7919 bytes)
[2024-11-10T00:00:22.625+0000] {spark_submit.py:634} INFO - 24/11/10 00:00:22 INFO TaskSetManager: Finished task 3.0 in stage 1.0 (TID 4) in 2667 ms on 172.23.0.5 (executor 0) (4/202)
[2024-11-10T00:00:24.656+0000] {spark_submit.py:634} INFO - 24/11/10 00:00:24 INFO TaskSetManager: Starting task 6.0 in stage 1.0 (TID 7) (172.23.0.5, executor 0, partition 6, PROCESS_LOCAL, 7919 bytes)
[2024-11-10T00:00:24.657+0000] {spark_submit.py:634} INFO - 24/11/10 00:00:24 INFO TaskSetManager: Finished task 4.0 in stage 1.0 (TID 5) in 2420 ms on 172.23.0.5 (executor 0) (5/202)
[2024-11-10T00:00:25.135+0000] {spark_submit.py:634} INFO - 24/11/10 00:00:25 INFO TaskSetManager: Starting task 7.0 in stage 1.0 (TID 8) (172.23.0.5, executor 0, partition 7, PROCESS_LOCAL, 7919 bytes)
[2024-11-10T00:00:25.136+0000] {spark_submit.py:634} INFO - 24/11/10 00:00:25 INFO TaskSetManager: Finished task 5.0 in stage 1.0 (TID 6) in 2514 ms on 172.23.0.5 (executor 0) (6/202)
[2024-11-10T00:00:27.050+0000] {spark_submit.py:634} INFO - 24/11/10 00:00:27 INFO TaskSetManager: Starting task 8.0 in stage 1.0 (TID 9) (172.23.0.5, executor 0, partition 8, PROCESS_LOCAL, 7919 bytes)
[2024-11-10T00:00:27.051+0000] {spark_submit.py:634} INFO - 24/11/10 00:00:27 INFO TaskSetManager: Finished task 6.0 in stage 1.0 (TID 7) in 2394 ms on 172.23.0.5 (executor 0) (7/202)
[2024-11-10T00:00:27.632+0000] {spark_submit.py:634} INFO - 24/11/10 00:00:27 INFO TaskSetManager: Starting task 9.0 in stage 1.0 (TID 10) (172.23.0.5, executor 0, partition 9, PROCESS_LOCAL, 7919 bytes)
[2024-11-10T00:00:27.633+0000] {spark_submit.py:634} INFO - 24/11/10 00:00:27 INFO TaskSetManager: Finished task 7.0 in stage 1.0 (TID 8) in 2497 ms on 172.23.0.5 (executor 0) (8/202)
[2024-11-10T00:00:29.440+0000] {spark_submit.py:634} INFO - 24/11/10 00:00:29 INFO TaskSetManager: Starting task 10.0 in stage 1.0 (TID 11) (172.23.0.5, executor 0, partition 10, PROCESS_LOCAL, 7919 bytes)
[2024-11-10T00:00:29.442+0000] {spark_submit.py:634} INFO - 24/11/10 00:00:29 INFO TaskSetManager: Finished task 8.0 in stage 1.0 (TID 9) in 2392 ms on 172.23.0.5 (executor 0) (9/202)
[2024-11-10T00:00:30.233+0000] {spark_submit.py:634} INFO - 24/11/10 00:00:30 INFO TaskSetManager: Starting task 11.0 in stage 1.0 (TID 12) (172.23.0.5, executor 0, partition 11, PROCESS_LOCAL, 7919 bytes)
[2024-11-10T00:00:30.234+0000] {spark_submit.py:634} INFO - 24/11/10 00:00:30 INFO TaskSetManager: Finished task 9.0 in stage 1.0 (TID 10) in 2602 ms on 172.23.0.5 (executor 0) (10/202)
[2024-11-10T00:00:31.838+0000] {spark_submit.py:634} INFO - 24/11/10 00:00:31 INFO TaskSetManager: Starting task 12.0 in stage 1.0 (TID 13) (172.23.0.5, executor 0, partition 12, PROCESS_LOCAL, 7919 bytes)
[2024-11-10T00:00:31.839+0000] {spark_submit.py:634} INFO - 24/11/10 00:00:31 INFO TaskSetManager: Finished task 10.0 in stage 1.0 (TID 11) in 2398 ms on 172.23.0.5 (executor 0) (11/202)
[2024-11-10T00:00:32.693+0000] {spark_submit.py:634} INFO - 24/11/10 00:00:32 INFO TaskSetManager: Starting task 13.0 in stage 1.0 (TID 14) (172.23.0.5, executor 0, partition 13, PROCESS_LOCAL, 7919 bytes)
[2024-11-10T00:00:32.694+0000] {spark_submit.py:634} INFO - 24/11/10 00:00:32 INFO TaskSetManager: Finished task 11.0 in stage 1.0 (TID 12) in 2461 ms on 172.23.0.5 (executor 0) (12/202)
[2024-11-10T00:00:34.315+0000] {spark_submit.py:634} INFO - 24/11/10 00:00:34 INFO TaskSetManager: Starting task 14.0 in stage 1.0 (TID 15) (172.23.0.5, executor 0, partition 14, PROCESS_LOCAL, 7919 bytes)
[2024-11-10T00:00:34.316+0000] {spark_submit.py:634} INFO - 24/11/10 00:00:34 INFO TaskSetManager: Finished task 12.0 in stage 1.0 (TID 13) in 2478 ms on 172.23.0.5 (executor 0) (13/202)
[2024-11-10T00:00:35.193+0000] {spark_submit.py:634} INFO - 24/11/10 00:00:35 INFO TaskSetManager: Starting task 15.0 in stage 1.0 (TID 16) (172.23.0.5, executor 0, partition 15, PROCESS_LOCAL, 7919 bytes)
[2024-11-10T00:00:35.194+0000] {spark_submit.py:634} INFO - 24/11/10 00:00:35 INFO TaskSetManager: Finished task 13.0 in stage 1.0 (TID 14) in 2502 ms on 172.23.0.5 (executor 0) (14/202)
[2024-11-10T00:00:36.690+0000] {spark_submit.py:634} INFO - 24/11/10 00:00:36 INFO TaskSetManager: Starting task 16.0 in stage 1.0 (TID 17) (172.23.0.5, executor 0, partition 16, PROCESS_LOCAL, 7919 bytes)
[2024-11-10T00:00:36.693+0000] {spark_submit.py:634} INFO - 24/11/10 00:00:36 INFO TaskSetManager: Finished task 14.0 in stage 1.0 (TID 15) in 2376 ms on 172.23.0.5 (executor 0) (15/202)
[2024-11-10T00:00:37.692+0000] {spark_submit.py:634} INFO - 24/11/10 00:00:37 INFO TaskSetManager: Starting task 17.0 in stage 1.0 (TID 18) (172.23.0.5, executor 0, partition 17, PROCESS_LOCAL, 7919 bytes)
[2024-11-10T00:00:37.693+0000] {spark_submit.py:634} INFO - 24/11/10 00:00:37 INFO TaskSetManager: Finished task 15.0 in stage 1.0 (TID 16) in 2501 ms on 172.23.0.5 (executor 0) (16/202)
[2024-11-10T00:00:39.066+0000] {spark_submit.py:634} INFO - 24/11/10 00:00:39 INFO TaskSetManager: Starting task 18.0 in stage 1.0 (TID 19) (172.23.0.5, executor 0, partition 18, PROCESS_LOCAL, 7919 bytes)
[2024-11-10T00:00:39.068+0000] {spark_submit.py:634} INFO - 24/11/10 00:00:39 INFO TaskSetManager: Finished task 16.0 in stage 1.0 (TID 17) in 2377 ms on 172.23.0.5 (executor 0) (17/202)
[2024-11-10T00:00:40.106+0000] {spark_submit.py:634} INFO - 24/11/10 00:00:40 INFO TaskSetManager: Starting task 19.0 in stage 1.0 (TID 20) (172.23.0.5, executor 0, partition 19, PROCESS_LOCAL, 7919 bytes)
[2024-11-10T00:00:40.108+0000] {spark_submit.py:634} INFO - 24/11/10 00:00:40 INFO TaskSetManager: Finished task 17.0 in stage 1.0 (TID 18) in 2416 ms on 172.23.0.5 (executor 0) (18/202)
[2024-11-10T00:00:41.532+0000] {spark_submit.py:634} INFO - 24/11/10 00:00:41 INFO TaskSetManager: Starting task 20.0 in stage 1.0 (TID 21) (172.23.0.5, executor 0, partition 20, PROCESS_LOCAL, 7919 bytes)
[2024-11-10T00:00:41.533+0000] {spark_submit.py:634} INFO - 24/11/10 00:00:41 INFO TaskSetManager: Finished task 18.0 in stage 1.0 (TID 19) in 2468 ms on 172.23.0.5 (executor 0) (19/202)
[2024-11-10T00:00:42.456+0000] {spark_submit.py:634} INFO - 24/11/10 00:00:42 INFO TaskSetManager: Starting task 21.0 in stage 1.0 (TID 22) (172.23.0.5, executor 0, partition 21, PROCESS_LOCAL, 7919 bytes)
[2024-11-10T00:00:42.457+0000] {spark_submit.py:634} INFO - 24/11/10 00:00:42 INFO TaskSetManager: Finished task 19.0 in stage 1.0 (TID 20) in 2351 ms on 172.23.0.5 (executor 0) (20/202)
[2024-11-10T00:00:43.886+0000] {spark_submit.py:634} INFO - 24/11/10 00:00:43 INFO TaskSetManager: Starting task 22.0 in stage 1.0 (TID 23) (172.23.0.5, executor 0, partition 22, PROCESS_LOCAL, 7919 bytes)
[2024-11-10T00:00:43.888+0000] {spark_submit.py:634} INFO - 24/11/10 00:00:43 INFO TaskSetManager: Finished task 20.0 in stage 1.0 (TID 21) in 2355 ms on 172.23.0.5 (executor 0) (21/202)
[2024-11-10T00:00:44.658+0000] {spark_submit.py:634} INFO - 24/11/10 00:00:44 INFO TaskSetManager: Starting task 23.0 in stage 1.0 (TID 24) (172.23.0.5, executor 0, partition 23, PROCESS_LOCAL, 7919 bytes)
[2024-11-10T00:00:44.659+0000] {spark_submit.py:634} INFO - 24/11/10 00:00:44 INFO TaskSetManager: Finished task 21.0 in stage 1.0 (TID 22) in 2202 ms on 172.23.0.5 (executor 0) (22/202)
[2024-11-10T00:00:46.264+0000] {spark_submit.py:634} INFO - 24/11/10 00:00:46 INFO TaskSetManager: Starting task 24.0 in stage 1.0 (TID 25) (172.23.0.5, executor 0, partition 24, PROCESS_LOCAL, 7919 bytes)
[2024-11-10T00:00:46.265+0000] {spark_submit.py:634} INFO - 24/11/10 00:00:46 INFO TaskSetManager: Finished task 22.0 in stage 1.0 (TID 23) in 2379 ms on 172.23.0.5 (executor 0) (23/202)
[2024-11-10T00:00:47.088+0000] {spark_submit.py:634} INFO - 24/11/10 00:00:47 INFO TaskSetManager: Starting task 25.0 in stage 1.0 (TID 26) (172.23.0.5, executor 0, partition 25, PROCESS_LOCAL, 7919 bytes)
[2024-11-10T00:00:47.089+0000] {spark_submit.py:634} INFO - 24/11/10 00:00:47 INFO TaskSetManager: Finished task 23.0 in stage 1.0 (TID 24) in 2431 ms on 172.23.0.5 (executor 0) (24/202)
[2024-11-10T00:00:48.614+0000] {spark_submit.py:634} INFO - 24/11/10 00:00:48 INFO TaskSetManager: Starting task 26.0 in stage 1.0 (TID 27) (172.23.0.5, executor 0, partition 26, PROCESS_LOCAL, 7919 bytes)
[2024-11-10T00:00:48.615+0000] {spark_submit.py:634} INFO - 24/11/10 00:00:48 INFO TaskSetManager: Finished task 24.0 in stage 1.0 (TID 25) in 2350 ms on 172.23.0.5 (executor 0) (25/202)
[2024-11-10T00:00:49.494+0000] {spark_submit.py:634} INFO - 24/11/10 00:00:49 INFO TaskSetManager: Starting task 27.0 in stage 1.0 (TID 28) (172.23.0.5, executor 0, partition 27, PROCESS_LOCAL, 7919 bytes)
[2024-11-10T00:00:49.500+0000] {spark_submit.py:634} INFO - 24/11/10 00:00:49 INFO TaskSetManager: Finished task 25.0 in stage 1.0 (TID 26) in 2407 ms on 172.23.0.5 (executor 0) (26/202)
[2024-11-10T00:00:50.962+0000] {spark_submit.py:634} INFO - 24/11/10 00:00:50 INFO TaskSetManager: Starting task 28.0 in stage 1.0 (TID 29) (172.23.0.5, executor 0, partition 28, PROCESS_LOCAL, 7919 bytes)
[2024-11-10T00:00:50.963+0000] {spark_submit.py:634} INFO - 24/11/10 00:00:50 INFO TaskSetManager: Finished task 26.0 in stage 1.0 (TID 27) in 2349 ms on 172.23.0.5 (executor 0) (27/202)
[2024-11-10T00:00:51.898+0000] {spark_submit.py:634} INFO - 24/11/10 00:00:51 INFO TaskSetManager: Starting task 29.0 in stage 1.0 (TID 30) (172.23.0.5, executor 0, partition 29, PROCESS_LOCAL, 7919 bytes)
[2024-11-10T00:00:51.899+0000] {spark_submit.py:634} INFO - 24/11/10 00:00:51 INFO TaskSetManager: Finished task 27.0 in stage 1.0 (TID 28) in 2404 ms on 172.23.0.5 (executor 0) (28/202)
[2024-11-10T00:00:53.338+0000] {spark_submit.py:634} INFO - 24/11/10 00:00:53 INFO TaskSetManager: Starting task 30.0 in stage 1.0 (TID 31) (172.23.0.5, executor 0, partition 30, PROCESS_LOCAL, 7919 bytes)
[2024-11-10T00:00:53.340+0000] {spark_submit.py:634} INFO - 24/11/10 00:00:53 INFO TaskSetManager: Finished task 28.0 in stage 1.0 (TID 29) in 2376 ms on 172.23.0.5 (executor 0) (29/202)
[2024-11-10T00:00:54.324+0000] {spark_submit.py:634} INFO - 24/11/10 00:00:54 INFO TaskSetManager: Starting task 31.0 in stage 1.0 (TID 32) (172.23.0.5, executor 0, partition 31, PROCESS_LOCAL, 7919 bytes)
[2024-11-10T00:00:54.326+0000] {spark_submit.py:634} INFO - 24/11/10 00:00:54 INFO TaskSetManager: Finished task 29.0 in stage 1.0 (TID 30) in 2428 ms on 172.23.0.5 (executor 0) (30/202)
[2024-11-10T00:00:55.681+0000] {spark_submit.py:634} INFO - 24/11/10 00:00:55 INFO TaskSetManager: Starting task 32.0 in stage 1.0 (TID 33) (172.23.0.5, executor 0, partition 32, PROCESS_LOCAL, 7919 bytes)
[2024-11-10T00:00:55.683+0000] {spark_submit.py:634} INFO - 24/11/10 00:00:55 INFO TaskSetManager: Finished task 30.0 in stage 1.0 (TID 31) in 2343 ms on 172.23.0.5 (executor 0) (31/202)
[2024-11-10T00:00:56.777+0000] {spark_submit.py:634} INFO - 24/11/10 00:00:56 INFO TaskSetManager: Starting task 33.0 in stage 1.0 (TID 34) (172.23.0.5, executor 0, partition 33, PROCESS_LOCAL, 7919 bytes)
[2024-11-10T00:00:56.778+0000] {spark_submit.py:634} INFO - 24/11/10 00:00:56 INFO TaskSetManager: Finished task 31.0 in stage 1.0 (TID 32) in 2453 ms on 172.23.0.5 (executor 0) (32/202)
[2024-11-10T00:00:58.090+0000] {spark_submit.py:634} INFO - 24/11/10 00:00:58 INFO TaskSetManager: Starting task 34.0 in stage 1.0 (TID 35) (172.23.0.5, executor 0, partition 34, PROCESS_LOCAL, 7919 bytes)
[2024-11-10T00:00:58.091+0000] {spark_submit.py:634} INFO - 24/11/10 00:00:58 INFO TaskSetManager: Finished task 32.0 in stage 1.0 (TID 33) in 2409 ms on 172.23.0.5 (executor 0) (33/202)
[2024-11-10T00:00:59.197+0000] {spark_submit.py:634} INFO - 24/11/10 00:00:59 INFO TaskSetManager: Starting task 35.0 in stage 1.0 (TID 36) (172.23.0.5, executor 0, partition 35, PROCESS_LOCAL, 7919 bytes)
[2024-11-10T00:00:59.198+0000] {spark_submit.py:634} INFO - 24/11/10 00:00:59 INFO TaskSetManager: Finished task 33.0 in stage 1.0 (TID 34) in 2421 ms on 172.23.0.5 (executor 0) (34/202)
[2024-11-10T00:01:00.517+0000] {spark_submit.py:634} INFO - 24/11/10 00:01:00 INFO TaskSetManager: Starting task 36.0 in stage 1.0 (TID 37) (172.23.0.5, executor 0, partition 36, PROCESS_LOCAL, 7919 bytes)
[2024-11-10T00:01:00.519+0000] {spark_submit.py:634} INFO - 24/11/10 00:01:00 INFO TaskSetManager: Finished task 34.0 in stage 1.0 (TID 35) in 2429 ms on 172.23.0.5 (executor 0) (35/202)
[2024-11-10T00:01:01.620+0000] {spark_submit.py:634} INFO - 24/11/10 00:01:01 INFO TaskSetManager: Starting task 37.0 in stage 1.0 (TID 38) (172.23.0.5, executor 0, partition 37, PROCESS_LOCAL, 7919 bytes)
[2024-11-10T00:01:01.621+0000] {spark_submit.py:634} INFO - 24/11/10 00:01:01 INFO TaskSetManager: Finished task 35.0 in stage 1.0 (TID 36) in 2423 ms on 172.23.0.5 (executor 0) (36/202)
[2024-11-10T00:01:02.888+0000] {spark_submit.py:634} INFO - 24/11/10 00:01:02 INFO TaskSetManager: Starting task 38.0 in stage 1.0 (TID 39) (172.23.0.5, executor 0, partition 38, PROCESS_LOCAL, 7919 bytes)
[2024-11-10T00:01:02.889+0000] {spark_submit.py:634} INFO - 24/11/10 00:01:02 INFO TaskSetManager: Finished task 36.0 in stage 1.0 (TID 37) in 2371 ms on 172.23.0.5 (executor 0) (37/202)
[2024-11-10T00:01:04.030+0000] {spark_submit.py:634} INFO - 24/11/10 00:01:04 INFO TaskSetManager: Starting task 39.0 in stage 1.0 (TID 40) (172.23.0.5, executor 0, partition 39, PROCESS_LOCAL, 7919 bytes)
[2024-11-10T00:01:04.031+0000] {spark_submit.py:634} INFO - 24/11/10 00:01:04 INFO TaskSetManager: Finished task 37.0 in stage 1.0 (TID 38) in 2411 ms on 172.23.0.5 (executor 0) (38/202)
[2024-11-10T00:01:05.293+0000] {spark_submit.py:634} INFO - 24/11/10 00:01:05 INFO TaskSetManager: Starting task 40.0 in stage 1.0 (TID 41) (172.23.0.5, executor 0, partition 40, PROCESS_LOCAL, 7919 bytes)
[2024-11-10T00:01:05.294+0000] {spark_submit.py:634} INFO - 24/11/10 00:01:05 INFO TaskSetManager: Finished task 38.0 in stage 1.0 (TID 39) in 2406 ms on 172.23.0.5 (executor 0) (39/202)
[2024-11-10T00:01:06.582+0000] {spark_submit.py:634} INFO - 24/11/10 00:01:06 INFO TaskSetManager: Starting task 41.0 in stage 1.0 (TID 42) (172.23.0.5, executor 0, partition 41, PROCESS_LOCAL, 7919 bytes)
[2024-11-10T00:01:06.583+0000] {spark_submit.py:634} INFO - 24/11/10 00:01:06 INFO TaskSetManager: Finished task 39.0 in stage 1.0 (TID 40) in 2554 ms on 172.23.0.5 (executor 0) (40/202)
[2024-11-10T00:01:07.712+0000] {spark_submit.py:634} INFO - 24/11/10 00:01:07 INFO TaskSetManager: Starting task 42.0 in stage 1.0 (TID 43) (172.23.0.5, executor 0, partition 42, PROCESS_LOCAL, 7919 bytes)
[2024-11-10T00:01:07.713+0000] {spark_submit.py:634} INFO - 24/11/10 00:01:07 INFO TaskSetManager: Finished task 40.0 in stage 1.0 (TID 41) in 2419 ms on 172.23.0.5 (executor 0) (41/202)
[2024-11-10T00:01:09.029+0000] {spark_submit.py:634} INFO - 24/11/10 00:01:09 INFO TaskSetManager: Starting task 43.0 in stage 1.0 (TID 44) (172.23.0.5, executor 0, partition 43, PROCESS_LOCAL, 7919 bytes)
[2024-11-10T00:01:09.030+0000] {spark_submit.py:634} INFO - 24/11/10 00:01:09 INFO TaskSetManager: Finished task 41.0 in stage 1.0 (TID 42) in 2448 ms on 172.23.0.5 (executor 0) (42/202)
[2024-11-10T00:01:10.168+0000] {spark_submit.py:634} INFO - 24/11/10 00:01:10 INFO TaskSetManager: Starting task 44.0 in stage 1.0 (TID 45) (172.23.0.5, executor 0, partition 44, PROCESS_LOCAL, 7919 bytes)
[2024-11-10T00:01:10.169+0000] {spark_submit.py:634} INFO - 24/11/10 00:01:10 INFO TaskSetManager: Finished task 42.0 in stage 1.0 (TID 43) in 2457 ms on 172.23.0.5 (executor 0) (43/202)
[2024-11-10T00:01:11.558+0000] {spark_submit.py:634} INFO - 24/11/10 00:01:11 INFO TaskSetManager: Starting task 45.0 in stage 1.0 (TID 46) (172.23.0.5, executor 0, partition 45, PROCESS_LOCAL, 7919 bytes)
[2024-11-10T00:01:11.560+0000] {spark_submit.py:634} INFO - 24/11/10 00:01:11 INFO TaskSetManager: Finished task 43.0 in stage 1.0 (TID 44) in 2530 ms on 172.23.0.5 (executor 0) (44/202)
[2024-11-10T00:01:12.571+0000] {spark_submit.py:634} INFO - 24/11/10 00:01:12 INFO TaskSetManager: Starting task 46.0 in stage 1.0 (TID 47) (172.23.0.5, executor 0, partition 46, PROCESS_LOCAL, 7919 bytes)
[2024-11-10T00:01:12.572+0000] {spark_submit.py:634} INFO - 24/11/10 00:01:12 INFO TaskSetManager: Finished task 44.0 in stage 1.0 (TID 45) in 2404 ms on 172.23.0.5 (executor 0) (45/202)
[2024-11-10T00:01:13.975+0000] {spark_submit.py:634} INFO - 24/11/10 00:01:13 INFO TaskSetManager: Starting task 47.0 in stage 1.0 (TID 48) (172.23.0.5, executor 0, partition 47, PROCESS_LOCAL, 7919 bytes)
[2024-11-10T00:01:13.976+0000] {spark_submit.py:634} INFO - 24/11/10 00:01:13 INFO TaskSetManager: Finished task 45.0 in stage 1.0 (TID 46) in 2417 ms on 172.23.0.5 (executor 0) (46/202)
[2024-11-10T00:01:15.030+0000] {spark_submit.py:634} INFO - 24/11/10 00:01:15 INFO TaskSetManager: Starting task 48.0 in stage 1.0 (TID 49) (172.23.0.5, executor 0, partition 48, PROCESS_LOCAL, 7919 bytes)
[2024-11-10T00:01:15.031+0000] {spark_submit.py:634} INFO - 24/11/10 00:01:15 INFO TaskSetManager: Finished task 46.0 in stage 1.0 (TID 47) in 2460 ms on 172.23.0.5 (executor 0) (47/202)
[2024-11-10T00:01:16.384+0000] {spark_submit.py:634} INFO - 24/11/10 00:01:16 INFO TaskSetManager: Starting task 49.0 in stage 1.0 (TID 50) (172.23.0.5, executor 0, partition 49, PROCESS_LOCAL, 7919 bytes)
[2024-11-10T00:01:16.386+0000] {spark_submit.py:634} INFO - 24/11/10 00:01:16 INFO TaskSetManager: Finished task 47.0 in stage 1.0 (TID 48) in 2410 ms on 172.23.0.5 (executor 0) (48/202)
[2024-11-10T00:01:17.487+0000] {spark_submit.py:634} INFO - 24/11/10 00:01:17 INFO TaskSetManager: Starting task 50.0 in stage 1.0 (TID 51) (172.23.0.5, executor 0, partition 50, PROCESS_LOCAL, 7919 bytes)
[2024-11-10T00:01:17.489+0000] {spark_submit.py:634} INFO - 24/11/10 00:01:17 INFO TaskSetManager: Finished task 48.0 in stage 1.0 (TID 49) in 2457 ms on 172.23.0.5 (executor 0) (49/202)
[2024-11-10T00:01:18.788+0000] {spark_submit.py:634} INFO - 24/11/10 00:01:18 INFO TaskSetManager: Starting task 51.0 in stage 1.0 (TID 52) (172.23.0.5, executor 0, partition 51, PROCESS_LOCAL, 7919 bytes)
[2024-11-10T00:01:18.790+0000] {spark_submit.py:634} INFO - 24/11/10 00:01:18 INFO TaskSetManager: Finished task 49.0 in stage 1.0 (TID 50) in 2406 ms on 172.23.0.5 (executor 0) (50/202)
[2024-11-10T00:01:19.890+0000] {spark_submit.py:634} INFO - 24/11/10 00:01:19 INFO TaskSetManager: Starting task 52.0 in stage 1.0 (TID 53) (172.23.0.5, executor 0, partition 52, PROCESS_LOCAL, 7919 bytes)
[2024-11-10T00:01:19.892+0000] {spark_submit.py:634} INFO - 24/11/10 00:01:19 INFO TaskSetManager: Finished task 50.0 in stage 1.0 (TID 51) in 2405 ms on 172.23.0.5 (executor 0) (51/202)
[2024-11-10T00:01:21.252+0000] {spark_submit.py:634} INFO - 24/11/10 00:01:21 INFO TaskSetManager: Starting task 53.0 in stage 1.0 (TID 54) (172.23.0.5, executor 0, partition 53, PROCESS_LOCAL, 7919 bytes)
[2024-11-10T00:01:21.253+0000] {spark_submit.py:634} INFO - 24/11/10 00:01:21 INFO TaskSetManager: Finished task 51.0 in stage 1.0 (TID 52) in 2464 ms on 172.23.0.5 (executor 0) (52/202)
[2024-11-10T00:01:22.303+0000] {spark_submit.py:634} INFO - 24/11/10 00:01:22 INFO TaskSetManager: Starting task 54.0 in stage 1.0 (TID 55) (172.23.0.5, executor 0, partition 54, PROCESS_LOCAL, 7919 bytes)
[2024-11-10T00:01:22.307+0000] {spark_submit.py:634} INFO - 24/11/10 00:01:22 INFO TaskSetManager: Finished task 52.0 in stage 1.0 (TID 53) in 2413 ms on 172.23.0.5 (executor 0) (53/202)
[2024-11-10T00:01:23.702+0000] {spark_submit.py:634} INFO - 24/11/10 00:01:23 INFO TaskSetManager: Starting task 55.0 in stage 1.0 (TID 56) (172.23.0.5, executor 0, partition 55, PROCESS_LOCAL, 7919 bytes)
[2024-11-10T00:01:23.705+0000] {spark_submit.py:634} INFO - 24/11/10 00:01:23 INFO TaskSetManager: Finished task 53.0 in stage 1.0 (TID 54) in 2451 ms on 172.23.0.5 (executor 0) (54/202)
[2024-11-10T00:01:24.756+0000] {spark_submit.py:634} INFO - 24/11/10 00:01:24 INFO TaskSetManager: Starting task 56.0 in stage 1.0 (TID 57) (172.23.0.5, executor 0, partition 56, PROCESS_LOCAL, 7919 bytes)
[2024-11-10T00:01:24.757+0000] {spark_submit.py:634} INFO - 24/11/10 00:01:24 INFO TaskSetManager: Finished task 54.0 in stage 1.0 (TID 55) in 2454 ms on 172.23.0.5 (executor 0) (55/202)
[2024-11-10T00:01:26.142+0000] {spark_submit.py:634} INFO - 24/11/10 00:01:26 INFO TaskSetManager: Starting task 57.0 in stage 1.0 (TID 58) (172.23.0.5, executor 0, partition 57, PROCESS_LOCAL, 7919 bytes)
[2024-11-10T00:01:26.145+0000] {spark_submit.py:634} INFO - 24/11/10 00:01:26 INFO TaskSetManager: Finished task 55.0 in stage 1.0 (TID 56) in 2441 ms on 172.23.0.5 (executor 0) (56/202)
[2024-11-10T00:01:27.230+0000] {spark_submit.py:634} INFO - 24/11/10 00:01:27 INFO TaskSetManager: Starting task 58.0 in stage 1.0 (TID 59) (172.23.0.5, executor 0, partition 58, PROCESS_LOCAL, 7919 bytes)
[2024-11-10T00:01:27.232+0000] {spark_submit.py:634} INFO - 24/11/10 00:01:27 INFO TaskSetManager: Finished task 56.0 in stage 1.0 (TID 57) in 2475 ms on 172.23.0.5 (executor 0) (57/202)
[2024-11-10T00:01:28.553+0000] {spark_submit.py:634} INFO - 24/11/10 00:01:28 INFO TaskSetManager: Starting task 59.0 in stage 1.0 (TID 60) (172.23.0.5, executor 0, partition 59, PROCESS_LOCAL, 7919 bytes)
[2024-11-10T00:01:28.555+0000] {spark_submit.py:634} INFO - 24/11/10 00:01:28 INFO TaskSetManager: Finished task 57.0 in stage 1.0 (TID 58) in 2412 ms on 172.23.0.5 (executor 0) (58/202)
[2024-11-10T00:01:29.657+0000] {spark_submit.py:634} INFO - 24/11/10 00:01:29 INFO TaskSetManager: Starting task 60.0 in stage 1.0 (TID 61) (172.23.0.5, executor 0, partition 60, PROCESS_LOCAL, 7919 bytes)
[2024-11-10T00:01:29.659+0000] {spark_submit.py:634} INFO - 24/11/10 00:01:29 INFO TaskSetManager: Finished task 58.0 in stage 1.0 (TID 59) in 2428 ms on 172.23.0.5 (executor 0) (59/202)
[2024-11-10T00:01:30.984+0000] {spark_submit.py:634} INFO - 24/11/10 00:01:30 INFO TaskSetManager: Starting task 61.0 in stage 1.0 (TID 62) (172.23.0.5, executor 0, partition 61, PROCESS_LOCAL, 7919 bytes)
[2024-11-10T00:01:30.986+0000] {spark_submit.py:634} INFO - 24/11/10 00:01:30 INFO TaskSetManager: Finished task 59.0 in stage 1.0 (TID 60) in 2433 ms on 172.23.0.5 (executor 0) (60/202)
[2024-11-10T00:01:32.112+0000] {spark_submit.py:634} INFO - 24/11/10 00:01:32 INFO TaskSetManager: Starting task 62.0 in stage 1.0 (TID 63) (172.23.0.5, executor 0, partition 62, PROCESS_LOCAL, 7919 bytes)
[2024-11-10T00:01:32.114+0000] {spark_submit.py:634} INFO - 24/11/10 00:01:32 INFO TaskSetManager: Finished task 60.0 in stage 1.0 (TID 61) in 2456 ms on 172.23.0.5 (executor 0) (61/202)
[2024-11-10T00:01:33.414+0000] {spark_submit.py:634} INFO - 24/11/10 00:01:33 INFO TaskSetManager: Starting task 63.0 in stage 1.0 (TID 64) (172.23.0.5, executor 0, partition 63, PROCESS_LOCAL, 7919 bytes)
[2024-11-10T00:01:33.416+0000] {spark_submit.py:634} INFO - 24/11/10 00:01:33 INFO TaskSetManager: Finished task 61.0 in stage 1.0 (TID 62) in 2431 ms on 172.23.0.5 (executor 0) (62/202)
[2024-11-10T00:01:34.587+0000] {spark_submit.py:634} INFO - 24/11/10 00:01:34 INFO TaskSetManager: Starting task 64.0 in stage 1.0 (TID 65) (172.23.0.5, executor 0, partition 64, PROCESS_LOCAL, 7919 bytes)
[2024-11-10T00:01:34.588+0000] {spark_submit.py:634} INFO - 24/11/10 00:01:34 INFO TaskSetManager: Finished task 62.0 in stage 1.0 (TID 63) in 2475 ms on 172.23.0.5 (executor 0) (63/202)
[2024-11-10T00:01:35.837+0000] {spark_submit.py:634} INFO - 24/11/10 00:01:35 INFO TaskSetManager: Starting task 65.0 in stage 1.0 (TID 66) (172.23.0.5, executor 0, partition 65, PROCESS_LOCAL, 7919 bytes)
[2024-11-10T00:01:35.838+0000] {spark_submit.py:634} INFO - 24/11/10 00:01:35 INFO TaskSetManager: Finished task 63.0 in stage 1.0 (TID 64) in 2423 ms on 172.23.0.5 (executor 0) (64/202)
[2024-11-10T00:01:37.030+0000] {spark_submit.py:634} INFO - 24/11/10 00:01:37 INFO TaskSetManager: Starting task 66.0 in stage 1.0 (TID 67) (172.23.0.5, executor 0, partition 66, PROCESS_LOCAL, 7919 bytes)
[2024-11-10T00:01:37.032+0000] {spark_submit.py:634} INFO - 24/11/10 00:01:37 INFO TaskSetManager: Finished task 64.0 in stage 1.0 (TID 65) in 2445 ms on 172.23.0.5 (executor 0) (65/202)
[2024-11-10T00:01:38.271+0000] {spark_submit.py:634} INFO - 24/11/10 00:01:38 INFO TaskSetManager: Starting task 67.0 in stage 1.0 (TID 68) (172.23.0.5, executor 0, partition 67, PROCESS_LOCAL, 7919 bytes)
[2024-11-10T00:01:38.273+0000] {spark_submit.py:634} INFO - 24/11/10 00:01:38 INFO TaskSetManager: Finished task 65.0 in stage 1.0 (TID 66) in 2434 ms on 172.23.0.5 (executor 0) (66/202)
[2024-11-10T00:01:39.497+0000] {spark_submit.py:634} INFO - 24/11/10 00:01:39 INFO TaskSetManager: Starting task 68.0 in stage 1.0 (TID 69) (172.23.0.5, executor 0, partition 68, PROCESS_LOCAL, 7919 bytes)
[2024-11-10T00:01:39.499+0000] {spark_submit.py:634} INFO - 24/11/10 00:01:39 INFO TaskSetManager: Finished task 66.0 in stage 1.0 (TID 67) in 2467 ms on 172.23.0.5 (executor 0) (67/202)
[2024-11-10T00:01:40.667+0000] {spark_submit.py:634} INFO - 24/11/10 00:01:40 INFO TaskSetManager: Starting task 69.0 in stage 1.0 (TID 70) (172.23.0.5, executor 0, partition 69, PROCESS_LOCAL, 7919 bytes)
[2024-11-10T00:01:40.669+0000] {spark_submit.py:634} INFO - 24/11/10 00:01:40 INFO TaskSetManager: Finished task 67.0 in stage 1.0 (TID 68) in 2397 ms on 172.23.0.5 (executor 0) (68/202)
[2024-11-10T00:01:41.910+0000] {spark_submit.py:634} INFO - 24/11/10 00:01:41 INFO TaskSetManager: Starting task 70.0 in stage 1.0 (TID 71) (172.23.0.5, executor 0, partition 70, PROCESS_LOCAL, 7919 bytes)
[2024-11-10T00:01:41.911+0000] {spark_submit.py:634} INFO - 24/11/10 00:01:41 INFO TaskSetManager: Finished task 68.0 in stage 1.0 (TID 69) in 2413 ms on 172.23.0.5 (executor 0) (69/202)
[2024-11-10T00:01:43.076+0000] {spark_submit.py:634} INFO - 24/11/10 00:01:43 INFO TaskSetManager: Starting task 71.0 in stage 1.0 (TID 72) (172.23.0.5, executor 0, partition 71, PROCESS_LOCAL, 7919 bytes)
[2024-11-10T00:01:43.078+0000] {spark_submit.py:634} INFO - 24/11/10 00:01:43 INFO TaskSetManager: Finished task 69.0 in stage 1.0 (TID 70) in 2410 ms on 172.23.0.5 (executor 0) (70/202)
[2024-11-10T00:01:44.382+0000] {spark_submit.py:634} INFO - 24/11/10 00:01:44 INFO TaskSetManager: Starting task 72.0 in stage 1.0 (TID 73) (172.23.0.5, executor 0, partition 72, PROCESS_LOCAL, 7919 bytes)
[2024-11-10T00:01:44.384+0000] {spark_submit.py:634} INFO - 24/11/10 00:01:44 INFO TaskSetManager: Finished task 70.0 in stage 1.0 (TID 71) in 2473 ms on 172.23.0.5 (executor 0) (71/202)
[2024-11-10T00:01:45.525+0000] {spark_submit.py:634} INFO - 24/11/10 00:01:45 INFO TaskSetManager: Starting task 73.0 in stage 1.0 (TID 74) (172.23.0.5, executor 0, partition 73, PROCESS_LOCAL, 7919 bytes)
[2024-11-10T00:01:45.526+0000] {spark_submit.py:634} INFO - 24/11/10 00:01:45 INFO TaskSetManager: Finished task 71.0 in stage 1.0 (TID 72) in 2450 ms on 172.23.0.5 (executor 0) (72/202)
[2024-11-10T00:01:46.858+0000] {spark_submit.py:634} INFO - 24/11/10 00:01:46 INFO TaskSetManager: Starting task 74.0 in stage 1.0 (TID 75) (172.23.0.5, executor 0, partition 74, PROCESS_LOCAL, 7919 bytes)
[2024-11-10T00:01:46.859+0000] {spark_submit.py:634} INFO - 24/11/10 00:01:46 INFO TaskSetManager: Finished task 72.0 in stage 1.0 (TID 73) in 2477 ms on 172.23.0.5 (executor 0) (73/202)
[2024-11-10T00:01:48.012+0000] {spark_submit.py:634} INFO - 24/11/10 00:01:48 INFO TaskSetManager: Starting task 75.0 in stage 1.0 (TID 76) (172.23.0.5, executor 0, partition 75, PROCESS_LOCAL, 7919 bytes)
[2024-11-10T00:01:48.014+0000] {spark_submit.py:634} INFO - 24/11/10 00:01:48 INFO TaskSetManager: Finished task 73.0 in stage 1.0 (TID 74) in 2488 ms on 172.23.0.5 (executor 0) (74/202)
[2024-11-10T00:01:49.350+0000] {spark_submit.py:634} INFO - 24/11/10 00:01:49 INFO TaskSetManager: Starting task 76.0 in stage 1.0 (TID 77) (172.23.0.5, executor 0, partition 76, PROCESS_LOCAL, 7919 bytes)
[2024-11-10T00:01:49.351+0000] {spark_submit.py:634} INFO - 24/11/10 00:01:49 INFO TaskSetManager: Finished task 74.0 in stage 1.0 (TID 75) in 2493 ms on 172.23.0.5 (executor 0) (75/202)
[2024-11-10T00:01:50.486+0000] {spark_submit.py:634} INFO - 24/11/10 00:01:50 INFO TaskSetManager: Starting task 77.0 in stage 1.0 (TID 78) (172.23.0.5, executor 0, partition 77, PROCESS_LOCAL, 7919 bytes)
[2024-11-10T00:01:50.488+0000] {spark_submit.py:634} INFO - 24/11/10 00:01:50 INFO TaskSetManager: Finished task 75.0 in stage 1.0 (TID 76) in 2476 ms on 172.23.0.5 (executor 0) (76/202)
[2024-11-10T00:01:51.952+0000] {spark_submit.py:634} INFO - 24/11/10 00:01:51 INFO TaskSetManager: Starting task 78.0 in stage 1.0 (TID 79) (172.23.0.5, executor 0, partition 78, PROCESS_LOCAL, 7919 bytes)
[2024-11-10T00:01:51.953+0000] {spark_submit.py:634} INFO - 24/11/10 00:01:51 INFO TaskSetManager: Finished task 76.0 in stage 1.0 (TID 77) in 2603 ms on 172.23.0.5 (executor 0) (77/202)
[2024-11-10T00:01:52.894+0000] {spark_submit.py:634} INFO - 24/11/10 00:01:52 INFO TaskSetManager: Starting task 79.0 in stage 1.0 (TID 80) (172.23.0.5, executor 0, partition 79, PROCESS_LOCAL, 7919 bytes)
[2024-11-10T00:01:52.895+0000] {spark_submit.py:634} INFO - 24/11/10 00:01:52 INFO TaskSetManager: Finished task 77.0 in stage 1.0 (TID 78) in 2409 ms on 172.23.0.5 (executor 0) (78/202)
[2024-11-10T00:01:54.350+0000] {spark_submit.py:634} INFO - 24/11/10 00:01:54 INFO TaskSetManager: Starting task 80.0 in stage 1.0 (TID 81) (172.23.0.5, executor 0, partition 80, PROCESS_LOCAL, 7919 bytes)
[2024-11-10T00:01:54.351+0000] {spark_submit.py:634} INFO - 24/11/10 00:01:54 INFO TaskSetManager: Finished task 78.0 in stage 1.0 (TID 79) in 2398 ms on 172.23.0.5 (executor 0) (79/202)
[2024-11-10T00:01:55.347+0000] {spark_submit.py:634} INFO - 24/11/10 00:01:55 INFO TaskSetManager: Starting task 81.0 in stage 1.0 (TID 82) (172.23.0.5, executor 0, partition 81, PROCESS_LOCAL, 7919 bytes)
[2024-11-10T00:01:55.349+0000] {spark_submit.py:634} INFO - 24/11/10 00:01:55 INFO TaskSetManager: Finished task 79.0 in stage 1.0 (TID 80) in 2455 ms on 172.23.0.5 (executor 0) (80/202)
[2024-11-10T00:01:56.771+0000] {spark_submit.py:634} INFO - 24/11/10 00:01:56 INFO TaskSetManager: Starting task 82.0 in stage 1.0 (TID 83) (172.23.0.5, executor 0, partition 82, PROCESS_LOCAL, 7919 bytes)
[2024-11-10T00:01:56.772+0000] {spark_submit.py:634} INFO - 24/11/10 00:01:56 INFO TaskSetManager: Finished task 80.0 in stage 1.0 (TID 81) in 2422 ms on 172.23.0.5 (executor 0) (81/202)
[2024-11-10T00:01:57.916+0000] {spark_submit.py:634} INFO - 24/11/10 00:01:57 INFO TaskSetManager: Starting task 83.0 in stage 1.0 (TID 84) (172.23.0.5, executor 0, partition 83, PROCESS_LOCAL, 7919 bytes)
[2024-11-10T00:01:57.918+0000] {spark_submit.py:634} INFO - 24/11/10 00:01:57 INFO TaskSetManager: Finished task 81.0 in stage 1.0 (TID 82) in 2569 ms on 172.23.0.5 (executor 0) (82/202)
[2024-11-10T00:01:59.253+0000] {spark_submit.py:634} INFO - 24/11/10 00:01:59 INFO TaskSetManager: Starting task 84.0 in stage 1.0 (TID 85) (172.23.0.5, executor 0, partition 84, PROCESS_LOCAL, 7919 bytes)
[2024-11-10T00:01:59.255+0000] {spark_submit.py:634} INFO - 24/11/10 00:01:59 INFO TaskSetManager: Finished task 82.0 in stage 1.0 (TID 83) in 2484 ms on 172.23.0.5 (executor 0) (83/202)
[2024-11-10T00:02:00.430+0000] {spark_submit.py:634} INFO - 24/11/10 00:02:00 INFO TaskSetManager: Starting task 85.0 in stage 1.0 (TID 86) (172.23.0.5, executor 0, partition 85, PROCESS_LOCAL, 7919 bytes)
[2024-11-10T00:02:00.431+0000] {spark_submit.py:634} INFO - 24/11/10 00:02:00 INFO TaskSetManager: Finished task 83.0 in stage 1.0 (TID 84) in 2514 ms on 172.23.0.5 (executor 0) (84/202)
[2024-11-10T00:02:01.737+0000] {spark_submit.py:634} INFO - 24/11/10 00:02:01 INFO TaskSetManager: Starting task 86.0 in stage 1.0 (TID 87) (172.23.0.5, executor 0, partition 86, PROCESS_LOCAL, 7919 bytes)
[2024-11-10T00:02:01.738+0000] {spark_submit.py:634} INFO - 24/11/10 00:02:01 INFO TaskSetManager: Finished task 84.0 in stage 1.0 (TID 85) in 2484 ms on 172.23.0.5 (executor 0) (85/202)
[2024-11-10T00:02:02.983+0000] {spark_submit.py:634} INFO - 24/11/10 00:02:02 INFO TaskSetManager: Starting task 87.0 in stage 1.0 (TID 88) (172.23.0.5, executor 0, partition 87, PROCESS_LOCAL, 7919 bytes)
[2024-11-10T00:02:02.984+0000] {spark_submit.py:634} INFO - 24/11/10 00:02:02 INFO TaskSetManager: Finished task 85.0 in stage 1.0 (TID 86) in 2555 ms on 172.23.0.5 (executor 0) (86/202)
[2024-11-10T00:02:04.263+0000] {spark_submit.py:634} INFO - 24/11/10 00:02:04 INFO TaskSetManager: Starting task 88.0 in stage 1.0 (TID 89) (172.23.0.5, executor 0, partition 88, PROCESS_LOCAL, 7919 bytes)
[2024-11-10T00:02:04.264+0000] {spark_submit.py:634} INFO - 24/11/10 00:02:04 INFO TaskSetManager: Finished task 86.0 in stage 1.0 (TID 87) in 2527 ms on 172.23.0.5 (executor 0) (87/202)
[2024-11-10T00:02:05.504+0000] {spark_submit.py:634} INFO - 24/11/10 00:02:05 INFO TaskSetManager: Starting task 89.0 in stage 1.0 (TID 90) (172.23.0.5, executor 0, partition 89, PROCESS_LOCAL, 7919 bytes)
[2024-11-10T00:02:05.504+0000] {spark_submit.py:634} INFO - 24/11/10 00:02:05 INFO TaskSetManager: Finished task 87.0 in stage 1.0 (TID 88) in 2521 ms on 172.23.0.5 (executor 0) (88/202)
[2024-11-10T00:02:06.779+0000] {spark_submit.py:634} INFO - 24/11/10 00:02:06 INFO TaskSetManager: Starting task 90.0 in stage 1.0 (TID 91) (172.23.0.5, executor 0, partition 90, PROCESS_LOCAL, 7919 bytes)
[2024-11-10T00:02:06.780+0000] {spark_submit.py:634} INFO - 24/11/10 00:02:06 INFO TaskSetManager: Finished task 88.0 in stage 1.0 (TID 89) in 2516 ms on 172.23.0.5 (executor 0) (89/202)
[2024-11-10T00:02:08.028+0000] {spark_submit.py:634} INFO - 24/11/10 00:02:08 INFO TaskSetManager: Starting task 91.0 in stage 1.0 (TID 92) (172.23.0.5, executor 0, partition 91, PROCESS_LOCAL, 7919 bytes)
[2024-11-10T00:02:08.030+0000] {spark_submit.py:634} INFO - 24/11/10 00:02:08 INFO TaskSetManager: Finished task 89.0 in stage 1.0 (TID 90) in 2525 ms on 172.23.0.5 (executor 0) (90/202)
[2024-11-10T00:02:09.288+0000] {spark_submit.py:634} INFO - 24/11/10 00:02:09 INFO TaskSetManager: Starting task 92.0 in stage 1.0 (TID 93) (172.23.0.5, executor 0, partition 92, PROCESS_LOCAL, 7919 bytes)
[2024-11-10T00:02:09.289+0000] {spark_submit.py:634} INFO - 24/11/10 00:02:09 INFO TaskSetManager: Finished task 90.0 in stage 1.0 (TID 91) in 2510 ms on 172.23.0.5 (executor 0) (91/202)
[2024-11-10T00:02:10.584+0000] {spark_submit.py:634} INFO - 24/11/10 00:02:10 INFO TaskSetManager: Starting task 93.0 in stage 1.0 (TID 94) (172.23.0.5, executor 0, partition 93, PROCESS_LOCAL, 7919 bytes)
[2024-11-10T00:02:10.585+0000] {spark_submit.py:634} INFO - 24/11/10 00:02:10 INFO TaskSetManager: Finished task 91.0 in stage 1.0 (TID 92) in 2557 ms on 172.23.0.5 (executor 0) (92/202)
[2024-11-10T00:02:11.637+0000] {spark_submit.py:634} INFO - 24/11/10 00:02:11 INFO TaskSetManager: Starting task 94.0 in stage 1.0 (TID 95) (172.23.0.5, executor 0, partition 94, PROCESS_LOCAL, 7919 bytes)
[2024-11-10T00:02:11.639+0000] {spark_submit.py:634} INFO - 24/11/10 00:02:11 INFO TaskSetManager: Finished task 92.0 in stage 1.0 (TID 93) in 2351 ms on 172.23.0.5 (executor 0) (93/202)
[2024-11-10T00:02:13.204+0000] {spark_submit.py:634} INFO - 24/11/10 00:02:13 INFO TaskSetManager: Starting task 95.0 in stage 1.0 (TID 96) (172.23.0.5, executor 0, partition 95, PROCESS_LOCAL, 7919 bytes)
[2024-11-10T00:02:13.205+0000] {spark_submit.py:634} INFO - 24/11/10 00:02:13 INFO TaskSetManager: Finished task 93.0 in stage 1.0 (TID 94) in 2620 ms on 172.23.0.5 (executor 0) (94/202)
[2024-11-10T00:02:14.338+0000] {spark_submit.py:634} INFO - 24/11/10 00:02:14 INFO TaskSetManager: Starting task 96.0 in stage 1.0 (TID 97) (172.23.0.5, executor 0, partition 96, PROCESS_LOCAL, 7919 bytes)
[2024-11-10T00:02:14.340+0000] {spark_submit.py:634} INFO - 24/11/10 00:02:14 INFO TaskSetManager: Finished task 94.0 in stage 1.0 (TID 95) in 2702 ms on 172.23.0.5 (executor 0) (95/202)
[2024-11-10T00:02:15.767+0000] {spark_submit.py:634} INFO - 24/11/10 00:02:15 INFO TaskSetManager: Starting task 97.0 in stage 1.0 (TID 98) (172.23.0.5, executor 0, partition 97, PROCESS_LOCAL, 7919 bytes)
[2024-11-10T00:02:15.769+0000] {spark_submit.py:634} INFO - 24/11/10 00:02:15 INFO TaskSetManager: Finished task 95.0 in stage 1.0 (TID 96) in 2565 ms on 172.23.0.5 (executor 0) (96/202)
[2024-11-10T00:02:16.990+0000] {spark_submit.py:634} INFO - 24/11/10 00:02:16 INFO TaskSetManager: Starting task 98.0 in stage 1.0 (TID 99) (172.23.0.5, executor 0, partition 98, PROCESS_LOCAL, 7919 bytes)
[2024-11-10T00:02:16.992+0000] {spark_submit.py:634} INFO - 24/11/10 00:02:16 INFO TaskSetManager: Finished task 96.0 in stage 1.0 (TID 97) in 2653 ms on 172.23.0.5 (executor 0) (97/202)
[2024-11-10T00:02:18.382+0000] {spark_submit.py:634} INFO - 24/11/10 00:02:18 INFO TaskSetManager: Starting task 99.0 in stage 1.0 (TID 100) (172.23.0.5, executor 0, partition 99, PROCESS_LOCAL, 7919 bytes)
[2024-11-10T00:02:18.383+0000] {spark_submit.py:634} INFO - 24/11/10 00:02:18 INFO TaskSetManager: Finished task 97.0 in stage 1.0 (TID 98) in 2615 ms on 172.23.0.5 (executor 0) (98/202)
[2024-11-10T00:02:19.504+0000] {spark_submit.py:634} INFO - 24/11/10 00:02:19 INFO TaskSetManager: Starting task 100.0 in stage 1.0 (TID 101) (172.23.0.5, executor 0, partition 100, PROCESS_LOCAL, 7919 bytes)
[2024-11-10T00:02:19.506+0000] {spark_submit.py:634} INFO - 24/11/10 00:02:19 INFO TaskSetManager: Finished task 98.0 in stage 1.0 (TID 99) in 2514 ms on 172.23.0.5 (executor 0) (99/202)
[2024-11-10T00:02:20.778+0000] {spark_submit.py:634} INFO - 24/11/10 00:02:20 INFO TaskSetManager: Starting task 101.0 in stage 1.0 (TID 102) (172.23.0.5, executor 0, partition 101, PROCESS_LOCAL, 7919 bytes)
[2024-11-10T00:02:20.780+0000] {spark_submit.py:634} INFO - 24/11/10 00:02:20 INFO TaskSetManager: Finished task 99.0 in stage 1.0 (TID 100) in 2398 ms on 172.23.0.5 (executor 0) (100/202)
[2024-11-10T00:02:22.049+0000] {spark_submit.py:634} INFO - 24/11/10 00:02:22 INFO TaskSetManager: Starting task 102.0 in stage 1.0 (TID 103) (172.23.0.5, executor 0, partition 102, PROCESS_LOCAL, 7919 bytes)
[2024-11-10T00:02:22.050+0000] {spark_submit.py:634} INFO - 24/11/10 00:02:22 INFO TaskSetManager: Finished task 100.0 in stage 1.0 (TID 101) in 2545 ms on 172.23.0.5 (executor 0) (101/202)
[2024-11-10T00:02:23.240+0000] {spark_submit.py:634} INFO - 24/11/10 00:02:23 INFO TaskSetManager: Starting task 103.0 in stage 1.0 (TID 104) (172.23.0.5, executor 0, partition 103, PROCESS_LOCAL, 7919 bytes)
[2024-11-10T00:02:23.242+0000] {spark_submit.py:634} INFO - 24/11/10 00:02:23 INFO TaskSetManager: Finished task 101.0 in stage 1.0 (TID 102) in 2462 ms on 172.23.0.5 (executor 0) (102/202)
[2024-11-10T00:02:24.497+0000] {spark_submit.py:634} INFO - 24/11/10 00:02:24 INFO TaskSetManager: Starting task 104.0 in stage 1.0 (TID 105) (172.23.0.5, executor 0, partition 104, PROCESS_LOCAL, 7919 bytes)
[2024-11-10T00:02:24.499+0000] {spark_submit.py:634} INFO - 24/11/10 00:02:24 INFO TaskSetManager: Finished task 102.0 in stage 1.0 (TID 103) in 2450 ms on 172.23.0.5 (executor 0) (103/202)
[2024-11-10T00:02:25.798+0000] {spark_submit.py:634} INFO - 24/11/10 00:02:25 INFO TaskSetManager: Starting task 105.0 in stage 1.0 (TID 106) (172.23.0.5, executor 0, partition 105, PROCESS_LOCAL, 7919 bytes)
[2024-11-10T00:02:25.800+0000] {spark_submit.py:634} INFO - 24/11/10 00:02:25 INFO TaskSetManager: Finished task 103.0 in stage 1.0 (TID 104) in 2560 ms on 172.23.0.5 (executor 0) (104/202)
[2024-11-10T00:02:27.041+0000] {spark_submit.py:634} INFO - 24/11/10 00:02:27 INFO TaskSetManager: Starting task 106.0 in stage 1.0 (TID 107) (172.23.0.5, executor 0, partition 106, PROCESS_LOCAL, 7919 bytes)
[2024-11-10T00:02:27.043+0000] {spark_submit.py:634} INFO - 24/11/10 00:02:27 INFO TaskSetManager: Finished task 104.0 in stage 1.0 (TID 105) in 2544 ms on 172.23.0.5 (executor 0) (105/202)
[2024-11-10T00:02:28.320+0000] {spark_submit.py:634} INFO - 24/11/10 00:02:28 INFO TaskSetManager: Starting task 107.0 in stage 1.0 (TID 108) (172.23.0.5, executor 0, partition 107, PROCESS_LOCAL, 7919 bytes)
[2024-11-10T00:02:28.321+0000] {spark_submit.py:634} INFO - 24/11/10 00:02:28 INFO TaskSetManager: Finished task 105.0 in stage 1.0 (TID 106) in 2522 ms on 172.23.0.5 (executor 0) (106/202)
[2024-11-10T00:02:29.594+0000] {spark_submit.py:634} INFO - 24/11/10 00:02:29 INFO TaskSetManager: Starting task 108.0 in stage 1.0 (TID 109) (172.23.0.5, executor 0, partition 108, PROCESS_LOCAL, 7919 bytes)
[2024-11-10T00:02:29.595+0000] {spark_submit.py:634} INFO - 24/11/10 00:02:29 INFO TaskSetManager: Finished task 106.0 in stage 1.0 (TID 107) in 2553 ms on 172.23.0.5 (executor 0) (107/202)
[2024-11-10T00:02:30.888+0000] {spark_submit.py:634} INFO - 24/11/10 00:02:30 INFO TaskSetManager: Starting task 109.0 in stage 1.0 (TID 110) (172.23.0.5, executor 0, partition 109, PROCESS_LOCAL, 7919 bytes)
[2024-11-10T00:02:30.890+0000] {spark_submit.py:634} INFO - 24/11/10 00:02:30 INFO TaskSetManager: Finished task 107.0 in stage 1.0 (TID 108) in 2570 ms on 172.23.0.5 (executor 0) (108/202)
[2024-11-10T00:02:32.169+0000] {spark_submit.py:634} INFO - 24/11/10 00:02:32 INFO TaskSetManager: Starting task 110.0 in stage 1.0 (TID 111) (172.23.0.5, executor 0, partition 110, PROCESS_LOCAL, 7919 bytes)
[2024-11-10T00:02:32.171+0000] {spark_submit.py:634} INFO - 24/11/10 00:02:32 INFO TaskSetManager: Finished task 108.0 in stage 1.0 (TID 109) in 2577 ms on 172.23.0.5 (executor 0) (109/202)
[2024-11-10T00:02:33.283+0000] {spark_submit.py:634} INFO - 24/11/10 00:02:33 INFO TaskSetManager: Starting task 111.0 in stage 1.0 (TID 112) (172.23.0.5, executor 0, partition 111, PROCESS_LOCAL, 7919 bytes)
[2024-11-10T00:02:33.284+0000] {spark_submit.py:634} INFO - 24/11/10 00:02:33 INFO TaskSetManager: Finished task 109.0 in stage 1.0 (TID 110) in 2396 ms on 172.23.0.5 (executor 0) (110/202)
[2024-11-10T00:02:34.688+0000] {spark_submit.py:634} INFO - 24/11/10 00:02:34 INFO TaskSetManager: Starting task 112.0 in stage 1.0 (TID 113) (172.23.0.5, executor 0, partition 112, PROCESS_LOCAL, 7919 bytes)
[2024-11-10T00:02:34.689+0000] {spark_submit.py:634} INFO - 24/11/10 00:02:34 INFO TaskSetManager: Finished task 110.0 in stage 1.0 (TID 111) in 2520 ms on 172.23.0.5 (executor 0) (111/202)
[2024-11-10T00:02:35.828+0000] {spark_submit.py:634} INFO - 24/11/10 00:02:35 INFO TaskSetManager: Starting task 113.0 in stage 1.0 (TID 114) (172.23.0.5, executor 0, partition 113, PROCESS_LOCAL, 7919 bytes)
[2024-11-10T00:02:35.830+0000] {spark_submit.py:634} INFO - 24/11/10 00:02:35 INFO TaskSetManager: Finished task 111.0 in stage 1.0 (TID 112) in 2546 ms on 172.23.0.5 (executor 0) (112/202)
[2024-11-10T00:02:37.191+0000] {spark_submit.py:634} INFO - 24/11/10 00:02:37 INFO TaskSetManager: Starting task 114.0 in stage 1.0 (TID 115) (172.23.0.5, executor 0, partition 114, PROCESS_LOCAL, 7919 bytes)
[2024-11-10T00:02:37.192+0000] {spark_submit.py:634} INFO - 24/11/10 00:02:37 INFO TaskSetManager: Finished task 112.0 in stage 1.0 (TID 113) in 2503 ms on 172.23.0.5 (executor 0) (113/202)
[2024-11-10T00:02:38.298+0000] {spark_submit.py:634} INFO - 24/11/10 00:02:38 INFO TaskSetManager: Starting task 115.0 in stage 1.0 (TID 116) (172.23.0.5, executor 0, partition 115, PROCESS_LOCAL, 7919 bytes)
[2024-11-10T00:02:38.299+0000] {spark_submit.py:634} INFO - 24/11/10 00:02:38 INFO TaskSetManager: Finished task 113.0 in stage 1.0 (TID 114) in 2471 ms on 172.23.0.5 (executor 0) (114/202)
[2024-11-10T00:02:39.639+0000] {spark_submit.py:634} INFO - 24/11/10 00:02:39 INFO TaskSetManager: Starting task 116.0 in stage 1.0 (TID 117) (172.23.0.5, executor 0, partition 116, PROCESS_LOCAL, 7919 bytes)
[2024-11-10T00:02:39.640+0000] {spark_submit.py:634} INFO - 24/11/10 00:02:39 INFO TaskSetManager: Finished task 114.0 in stage 1.0 (TID 115) in 2449 ms on 172.23.0.5 (executor 0) (115/202)
[2024-11-10T00:02:40.798+0000] {spark_submit.py:634} INFO - 24/11/10 00:02:40 INFO TaskSetManager: Starting task 117.0 in stage 1.0 (TID 118) (172.23.0.5, executor 0, partition 117, PROCESS_LOCAL, 7919 bytes)
[2024-11-10T00:02:40.799+0000] {spark_submit.py:634} INFO - 24/11/10 00:02:40 INFO TaskSetManager: Finished task 115.0 in stage 1.0 (TID 116) in 2501 ms on 172.23.0.5 (executor 0) (116/202)
[2024-11-10T00:02:42.124+0000] {spark_submit.py:634} INFO - 24/11/10 00:02:42 INFO TaskSetManager: Starting task 118.0 in stage 1.0 (TID 119) (172.23.0.5, executor 0, partition 118, PROCESS_LOCAL, 7919 bytes)
[2024-11-10T00:02:42.125+0000] {spark_submit.py:634} INFO - 24/11/10 00:02:42 INFO TaskSetManager: Finished task 116.0 in stage 1.0 (TID 117) in 2486 ms on 172.23.0.5 (executor 0) (117/202)
[2024-11-10T00:02:43.334+0000] {spark_submit.py:634} INFO - 24/11/10 00:02:43 INFO TaskSetManager: Starting task 119.0 in stage 1.0 (TID 120) (172.23.0.5, executor 0, partition 119, PROCESS_LOCAL, 7919 bytes)
[2024-11-10T00:02:43.335+0000] {spark_submit.py:634} INFO - 24/11/10 00:02:43 INFO TaskSetManager: Finished task 117.0 in stage 1.0 (TID 118) in 2536 ms on 172.23.0.5 (executor 0) (118/202)
[2024-11-10T00:02:44.635+0000] {spark_submit.py:634} INFO - 24/11/10 00:02:44 INFO TaskSetManager: Starting task 120.0 in stage 1.0 (TID 121) (172.23.0.5, executor 0, partition 120, PROCESS_LOCAL, 7919 bytes)
[2024-11-10T00:02:44.636+0000] {spark_submit.py:634} INFO - 24/11/10 00:02:44 INFO TaskSetManager: Finished task 118.0 in stage 1.0 (TID 119) in 2513 ms on 172.23.0.5 (executor 0) (119/202)
[2024-11-10T00:02:45.836+0000] {spark_submit.py:634} INFO - 24/11/10 00:02:45 INFO TaskSetManager: Starting task 121.0 in stage 1.0 (TID 122) (172.23.0.5, executor 0, partition 121, PROCESS_LOCAL, 7919 bytes)
[2024-11-10T00:02:45.837+0000] {spark_submit.py:634} INFO - 24/11/10 00:02:45 INFO TaskSetManager: Finished task 119.0 in stage 1.0 (TID 120) in 2503 ms on 172.23.0.5 (executor 0) (120/202)
[2024-11-10T00:02:47.159+0000] {spark_submit.py:634} INFO - 24/11/10 00:02:47 INFO TaskSetManager: Starting task 122.0 in stage 1.0 (TID 123) (172.23.0.5, executor 0, partition 122, PROCESS_LOCAL, 7919 bytes)
[2024-11-10T00:02:47.160+0000] {spark_submit.py:634} INFO - 24/11/10 00:02:47 INFO TaskSetManager: Finished task 120.0 in stage 1.0 (TID 121) in 2524 ms on 172.23.0.5 (executor 0) (121/202)
[2024-11-10T00:02:48.216+0000] {spark_submit.py:634} INFO - 24/11/10 00:02:48 INFO TaskSetManager: Starting task 123.0 in stage 1.0 (TID 124) (172.23.0.5, executor 0, partition 123, PROCESS_LOCAL, 7919 bytes)
[2024-11-10T00:02:48.217+0000] {spark_submit.py:634} INFO - 24/11/10 00:02:48 INFO TaskSetManager: Finished task 121.0 in stage 1.0 (TID 122) in 2380 ms on 172.23.0.5 (executor 0) (122/202)
[2024-11-10T00:02:49.610+0000] {spark_submit.py:634} INFO - 24/11/10 00:02:49 INFO TaskSetManager: Starting task 124.0 in stage 1.0 (TID 125) (172.23.0.5, executor 0, partition 124, PROCESS_LOCAL, 7919 bytes)
[2024-11-10T00:02:49.611+0000] {spark_submit.py:634} INFO - 24/11/10 00:02:49 INFO TaskSetManager: Finished task 122.0 in stage 1.0 (TID 123) in 2452 ms on 172.23.0.5 (executor 0) (123/202)
[2024-11-10T00:02:50.721+0000] {spark_submit.py:634} INFO - 24/11/10 00:02:50 INFO TaskSetManager: Starting task 125.0 in stage 1.0 (TID 126) (172.23.0.5, executor 0, partition 125, PROCESS_LOCAL, 7919 bytes)
[2024-11-10T00:02:50.723+0000] {spark_submit.py:634} INFO - 24/11/10 00:02:50 INFO TaskSetManager: Finished task 123.0 in stage 1.0 (TID 124) in 2507 ms on 172.23.0.5 (executor 0) (124/202)
[2024-11-10T00:02:52.065+0000] {spark_submit.py:634} INFO - 24/11/10 00:02:52 INFO TaskSetManager: Starting task 126.0 in stage 1.0 (TID 127) (172.23.0.5, executor 0, partition 126, PROCESS_LOCAL, 7919 bytes)
[2024-11-10T00:02:52.066+0000] {spark_submit.py:634} INFO - 24/11/10 00:02:52 INFO TaskSetManager: Finished task 124.0 in stage 1.0 (TID 125) in 2455 ms on 172.23.0.5 (executor 0) (125/202)
[2024-11-10T00:02:53.273+0000] {spark_submit.py:634} INFO - 24/11/10 00:02:53 INFO TaskSetManager: Starting task 127.0 in stage 1.0 (TID 128) (172.23.0.5, executor 0, partition 127, PROCESS_LOCAL, 7919 bytes)
[2024-11-10T00:02:53.274+0000] {spark_submit.py:634} INFO - 24/11/10 00:02:53 INFO TaskSetManager: Finished task 125.0 in stage 1.0 (TID 126) in 2552 ms on 172.23.0.5 (executor 0) (126/202)
[2024-11-10T00:02:54.559+0000] {spark_submit.py:634} INFO - 24/11/10 00:02:54 INFO TaskSetManager: Starting task 128.0 in stage 1.0 (TID 129) (172.23.0.5, executor 0, partition 128, PROCESS_LOCAL, 7919 bytes)
[2024-11-10T00:02:54.560+0000] {spark_submit.py:634} INFO - 24/11/10 00:02:54 INFO TaskSetManager: Finished task 126.0 in stage 1.0 (TID 127) in 2495 ms on 172.23.0.5 (executor 0) (127/202)
[2024-11-10T00:02:55.811+0000] {spark_submit.py:634} INFO - 24/11/10 00:02:55 INFO TaskSetManager: Starting task 129.0 in stage 1.0 (TID 130) (172.23.0.5, executor 0, partition 129, PROCESS_LOCAL, 7919 bytes)
[2024-11-10T00:02:55.813+0000] {spark_submit.py:634} INFO - 24/11/10 00:02:55 INFO TaskSetManager: Finished task 127.0 in stage 1.0 (TID 128) in 2539 ms on 172.23.0.5 (executor 0) (128/202)
[2024-11-10T00:02:57.063+0000] {spark_submit.py:634} INFO - 24/11/10 00:02:57 INFO TaskSetManager: Starting task 130.0 in stage 1.0 (TID 131) (172.23.0.5, executor 0, partition 130, PROCESS_LOCAL, 7919 bytes)
[2024-11-10T00:02:57.064+0000] {spark_submit.py:634} INFO - 24/11/10 00:02:57 INFO TaskSetManager: Finished task 128.0 in stage 1.0 (TID 129) in 2505 ms on 172.23.0.5 (executor 0) (129/202)
[2024-11-10T00:02:58.376+0000] {spark_submit.py:634} INFO - 24/11/10 00:02:58 INFO TaskSetManager: Starting task 131.0 in stage 1.0 (TID 132) (172.23.0.5, executor 0, partition 131, PROCESS_LOCAL, 7919 bytes)
[2024-11-10T00:02:58.378+0000] {spark_submit.py:634} INFO - 24/11/10 00:02:58 INFO TaskSetManager: Finished task 129.0 in stage 1.0 (TID 130) in 2565 ms on 172.23.0.5 (executor 0) (130/202)
[2024-11-10T00:02:59.642+0000] {spark_submit.py:634} INFO - 24/11/10 00:02:59 INFO TaskSetManager: Starting task 132.0 in stage 1.0 (TID 133) (172.23.0.5, executor 0, partition 132, PROCESS_LOCAL, 7919 bytes)
[2024-11-10T00:02:59.644+0000] {spark_submit.py:634} INFO - 24/11/10 00:02:59 INFO TaskSetManager: Finished task 130.0 in stage 1.0 (TID 131) in 2580 ms on 172.23.0.5 (executor 0) (131/202)
[2024-11-10T00:03:00.949+0000] {spark_submit.py:634} INFO - 24/11/10 00:03:00 INFO TaskSetManager: Starting task 133.0 in stage 1.0 (TID 134) (172.23.0.5, executor 0, partition 133, PROCESS_LOCAL, 7919 bytes)
[2024-11-10T00:03:00.951+0000] {spark_submit.py:634} INFO - 24/11/10 00:03:00 INFO TaskSetManager: Finished task 131.0 in stage 1.0 (TID 132) in 2574 ms on 172.23.0.5 (executor 0) (132/202)
[2024-11-10T00:03:02.140+0000] {spark_submit.py:634} INFO - 24/11/10 00:03:02 INFO TaskSetManager: Starting task 134.0 in stage 1.0 (TID 135) (172.23.0.5, executor 0, partition 134, PROCESS_LOCAL, 7919 bytes)
[2024-11-10T00:03:02.141+0000] {spark_submit.py:634} INFO - 24/11/10 00:03:02 INFO TaskSetManager: Finished task 132.0 in stage 1.0 (TID 133) in 2498 ms on 172.23.0.5 (executor 0) (133/202)
[2024-11-10T00:03:03.555+0000] {spark_submit.py:634} INFO - 24/11/10 00:03:03 INFO TaskSetManager: Starting task 135.0 in stage 1.0 (TID 136) (172.23.0.5, executor 0, partition 135, PROCESS_LOCAL, 7919 bytes)
[2024-11-10T00:03:03.557+0000] {spark_submit.py:634} INFO - 24/11/10 00:03:03 INFO TaskSetManager: Finished task 133.0 in stage 1.0 (TID 134) in 2608 ms on 172.23.0.5 (executor 0) (134/202)
[2024-11-10T00:03:04.719+0000] {spark_submit.py:634} INFO - 24/11/10 00:03:04 INFO TaskSetManager: Starting task 136.0 in stage 1.0 (TID 137) (172.23.0.5, executor 0, partition 136, PROCESS_LOCAL, 7919 bytes)
[2024-11-10T00:03:04.720+0000] {spark_submit.py:634} INFO - 24/11/10 00:03:04 INFO TaskSetManager: Finished task 134.0 in stage 1.0 (TID 135) in 2580 ms on 172.23.0.5 (executor 0) (135/202)
[2024-11-10T00:03:06.189+0000] {spark_submit.py:634} INFO - 24/11/10 00:03:06 INFO TaskSetManager: Starting task 137.0 in stage 1.0 (TID 138) (172.23.0.5, executor 0, partition 137, PROCESS_LOCAL, 7919 bytes)
[2024-11-10T00:03:06.191+0000] {spark_submit.py:634} INFO - 24/11/10 00:03:06 INFO TaskSetManager: Finished task 135.0 in stage 1.0 (TID 136) in 2634 ms on 172.23.0.5 (executor 0) (136/202)
[2024-11-10T00:03:07.269+0000] {spark_submit.py:634} INFO - 24/11/10 00:03:07 INFO TaskSetManager: Starting task 138.0 in stage 1.0 (TID 139) (172.23.0.5, executor 0, partition 138, PROCESS_LOCAL, 7919 bytes)
[2024-11-10T00:03:07.270+0000] {spark_submit.py:634} INFO - 24/11/10 00:03:07 INFO TaskSetManager: Finished task 136.0 in stage 1.0 (TID 137) in 2551 ms on 172.23.0.5 (executor 0) (137/202)
[2024-11-10T00:03:08.842+0000] {spark_submit.py:634} INFO - 24/11/10 00:03:08 INFO TaskSetManager: Starting task 139.0 in stage 1.0 (TID 140) (172.23.0.5, executor 0, partition 139, PROCESS_LOCAL, 7919 bytes)
[2024-11-10T00:03:08.844+0000] {spark_submit.py:634} INFO - 24/11/10 00:03:08 INFO TaskSetManager: Finished task 137.0 in stage 1.0 (TID 138) in 2653 ms on 172.23.0.5 (executor 0) (138/202)
[2024-11-10T00:03:09.665+0000] {spark_submit.py:634} INFO - 24/11/10 00:03:09 INFO TaskSetManager: Starting task 140.0 in stage 1.0 (TID 141) (172.23.0.5, executor 0, partition 140, PROCESS_LOCAL, 7919 bytes)
[2024-11-10T00:03:09.666+0000] {spark_submit.py:634} INFO - 24/11/10 00:03:09 INFO TaskSetManager: Finished task 138.0 in stage 1.0 (TID 139) in 2397 ms on 172.23.0.5 (executor 0) (139/202)
[2024-11-10T00:03:11.241+0000] {spark_submit.py:634} INFO - 24/11/10 00:03:11 INFO TaskSetManager: Starting task 141.0 in stage 1.0 (TID 142) (172.23.0.5, executor 0, partition 141, PROCESS_LOCAL, 7919 bytes)
[2024-11-10T00:03:11.242+0000] {spark_submit.py:634} INFO - 24/11/10 00:03:11 INFO TaskSetManager: Finished task 139.0 in stage 1.0 (TID 140) in 2399 ms on 172.23.0.5 (executor 0) (140/202)
[2024-11-10T00:03:12.174+0000] {spark_submit.py:634} INFO - 24/11/10 00:03:12 INFO TaskSetManager: Starting task 142.0 in stage 1.0 (TID 143) (172.23.0.5, executor 0, partition 142, PROCESS_LOCAL, 7919 bytes)
[2024-11-10T00:03:12.176+0000] {spark_submit.py:634} INFO - 24/11/10 00:03:12 INFO TaskSetManager: Finished task 140.0 in stage 1.0 (TID 141) in 2510 ms on 172.23.0.5 (executor 0) (141/202)
[2024-11-10T00:03:13.818+0000] {spark_submit.py:634} INFO - 24/11/10 00:03:13 INFO TaskSetManager: Starting task 143.0 in stage 1.0 (TID 144) (172.23.0.5, executor 0, partition 143, PROCESS_LOCAL, 7919 bytes)
[2024-11-10T00:03:13.820+0000] {spark_submit.py:634} INFO - 24/11/10 00:03:13 INFO TaskSetManager: Finished task 141.0 in stage 1.0 (TID 142) in 2577 ms on 172.23.0.5 (executor 0) (142/202)
[2024-11-10T00:03:14.484+0000] {spark_submit.py:634} INFO - 24/11/10 00:03:14 INFO TaskSetManager: Starting task 144.0 in stage 1.0 (TID 145) (172.23.0.5, executor 0, partition 144, PROCESS_LOCAL, 7919 bytes)
[2024-11-10T00:03:14.485+0000] {spark_submit.py:634} INFO - 24/11/10 00:03:14 INFO TaskSetManager: Finished task 142.0 in stage 1.0 (TID 143) in 2311 ms on 172.23.0.5 (executor 0) (143/202)
[2024-11-10T00:03:16.236+0000] {spark_submit.py:634} INFO - 24/11/10 00:03:16 INFO TaskSetManager: Starting task 145.0 in stage 1.0 (TID 146) (172.23.0.5, executor 0, partition 145, PROCESS_LOCAL, 7919 bytes)
[2024-11-10T00:03:16.237+0000] {spark_submit.py:634} INFO - 24/11/10 00:03:16 INFO TaskSetManager: Finished task 143.0 in stage 1.0 (TID 144) in 2420 ms on 172.23.0.5 (executor 0) (144/202)
[2024-11-10T00:03:16.996+0000] {spark_submit.py:634} INFO - 24/11/10 00:03:16 INFO TaskSetManager: Starting task 146.0 in stage 1.0 (TID 147) (172.23.0.5, executor 0, partition 146, PROCESS_LOCAL, 7919 bytes)
[2024-11-10T00:03:17.001+0000] {spark_submit.py:634} INFO - 24/11/10 00:03:17 INFO TaskSetManager: Finished task 144.0 in stage 1.0 (TID 145) in 2517 ms on 172.23.0.5 (executor 0) (145/202)
[2024-11-10T00:03:18.655+0000] {spark_submit.py:634} INFO - 24/11/10 00:03:18 INFO TaskSetManager: Starting task 147.0 in stage 1.0 (TID 148) (172.23.0.5, executor 0, partition 147, PROCESS_LOCAL, 7919 bytes)
[2024-11-10T00:03:18.657+0000] {spark_submit.py:634} INFO - 24/11/10 00:03:18 INFO TaskSetManager: Finished task 145.0 in stage 1.0 (TID 146) in 2419 ms on 172.23.0.5 (executor 0) (146/202)
[2024-11-10T00:03:19.598+0000] {spark_submit.py:634} INFO - 24/11/10 00:03:19 INFO TaskSetManager: Starting task 148.0 in stage 1.0 (TID 149) (172.23.0.5, executor 0, partition 148, PROCESS_LOCAL, 7919 bytes)
[2024-11-10T00:03:19.599+0000] {spark_submit.py:634} INFO - 24/11/10 00:03:19 INFO TaskSetManager: Finished task 146.0 in stage 1.0 (TID 147) in 2602 ms on 172.23.0.5 (executor 0) (147/202)
[2024-11-10T00:03:21.134+0000] {spark_submit.py:634} INFO - 24/11/10 00:03:21 INFO TaskSetManager: Starting task 149.0 in stage 1.0 (TID 150) (172.23.0.5, executor 0, partition 149, PROCESS_LOCAL, 7919 bytes)
[2024-11-10T00:03:21.135+0000] {spark_submit.py:634} INFO - 24/11/10 00:03:21 INFO TaskSetManager: Finished task 147.0 in stage 1.0 (TID 148) in 2479 ms on 172.23.0.5 (executor 0) (148/202)
[2024-11-10T00:03:22.070+0000] {spark_submit.py:634} INFO - 24/11/10 00:03:22 INFO TaskSetManager: Starting task 150.0 in stage 1.0 (TID 151) (172.23.0.5, executor 0, partition 150, PROCESS_LOCAL, 7919 bytes)
[2024-11-10T00:03:22.071+0000] {spark_submit.py:634} INFO - 24/11/10 00:03:22 INFO TaskSetManager: Finished task 148.0 in stage 1.0 (TID 149) in 2472 ms on 172.23.0.5 (executor 0) (149/202)
[2024-11-10T00:03:23.578+0000] {spark_submit.py:634} INFO - 24/11/10 00:03:23 INFO TaskSetManager: Starting task 151.0 in stage 1.0 (TID 152) (172.23.0.5, executor 0, partition 151, PROCESS_LOCAL, 7919 bytes)
[2024-11-10T00:03:23.579+0000] {spark_submit.py:634} INFO - 24/11/10 00:03:23 INFO TaskSetManager: Finished task 149.0 in stage 1.0 (TID 150) in 2444 ms on 172.23.0.5 (executor 0) (150/202)
[2024-11-10T00:03:24.584+0000] {spark_submit.py:634} INFO - 24/11/10 00:03:24 INFO TaskSetManager: Starting task 152.0 in stage 1.0 (TID 153) (172.23.0.5, executor 0, partition 152, PROCESS_LOCAL, 7919 bytes)
[2024-11-10T00:03:24.585+0000] {spark_submit.py:634} INFO - 24/11/10 00:03:24 INFO TaskSetManager: Finished task 150.0 in stage 1.0 (TID 151) in 2515 ms on 172.23.0.5 (executor 0) (151/202)
[2024-11-10T00:03:26.012+0000] {spark_submit.py:634} INFO - 24/11/10 00:03:26 INFO TaskSetManager: Starting task 153.0 in stage 1.0 (TID 154) (172.23.0.5, executor 0, partition 153, PROCESS_LOCAL, 7919 bytes)
[2024-11-10T00:03:26.013+0000] {spark_submit.py:634} INFO - 24/11/10 00:03:26 INFO TaskSetManager: Finished task 151.0 in stage 1.0 (TID 152) in 2434 ms on 172.23.0.5 (executor 0) (152/202)
[2024-11-10T00:03:27.062+0000] {spark_submit.py:634} INFO - 24/11/10 00:03:27 INFO TaskSetManager: Starting task 154.0 in stage 1.0 (TID 155) (172.23.0.5, executor 0, partition 154, PROCESS_LOCAL, 7919 bytes)
[2024-11-10T00:03:27.064+0000] {spark_submit.py:634} INFO - 24/11/10 00:03:27 INFO TaskSetManager: Finished task 152.0 in stage 1.0 (TID 153) in 2479 ms on 172.23.0.5 (executor 0) (153/202)
[2024-11-10T00:03:28.510+0000] {spark_submit.py:634} INFO - 24/11/10 00:03:28 INFO TaskSetManager: Starting task 155.0 in stage 1.0 (TID 156) (172.23.0.5, executor 0, partition 155, PROCESS_LOCAL, 7919 bytes)
[2024-11-10T00:03:28.511+0000] {spark_submit.py:634} INFO - 24/11/10 00:03:28 INFO TaskSetManager: Finished task 153.0 in stage 1.0 (TID 154) in 2499 ms on 172.23.0.5 (executor 0) (154/202)
[2024-11-10T00:03:29.508+0000] {spark_submit.py:634} INFO - 24/11/10 00:03:29 INFO TaskSetManager: Starting task 156.0 in stage 1.0 (TID 157) (172.23.0.5, executor 0, partition 156, PROCESS_LOCAL, 7919 bytes)
[2024-11-10T00:03:29.510+0000] {spark_submit.py:634} INFO - 24/11/10 00:03:29 INFO TaskSetManager: Finished task 154.0 in stage 1.0 (TID 155) in 2447 ms on 172.23.0.5 (executor 0) (155/202)
[2024-11-10T00:03:30.683+0000] {spark_submit.py:634} INFO - 24/11/10 00:03:30 INFO TaskSetManager: Starting task 157.0 in stage 1.0 (TID 158) (172.23.0.5, executor 0, partition 157, PROCESS_LOCAL, 7919 bytes)
[2024-11-10T00:03:30.685+0000] {spark_submit.py:634} INFO - 24/11/10 00:03:30 INFO TaskSetManager: Finished task 155.0 in stage 1.0 (TID 156) in 2175 ms on 172.23.0.5 (executor 0) (156/202)
[2024-11-10T00:03:31.967+0000] {spark_submit.py:634} INFO - 24/11/10 00:03:31 INFO TaskSetManager: Starting task 158.0 in stage 1.0 (TID 159) (172.23.0.5, executor 0, partition 158, PROCESS_LOCAL, 7919 bytes)
[2024-11-10T00:03:31.968+0000] {spark_submit.py:634} INFO - 24/11/10 00:03:31 INFO TaskSetManager: Finished task 156.0 in stage 1.0 (TID 157) in 2459 ms on 172.23.0.5 (executor 0) (157/202)
[2024-11-10T00:03:33.138+0000] {spark_submit.py:634} INFO - 24/11/10 00:03:33 INFO TaskSetManager: Starting task 159.0 in stage 1.0 (TID 160) (172.23.0.5, executor 0, partition 159, PROCESS_LOCAL, 7919 bytes)
[2024-11-10T00:03:33.139+0000] {spark_submit.py:634} INFO - 24/11/10 00:03:33 INFO TaskSetManager: Finished task 157.0 in stage 1.0 (TID 158) in 2455 ms on 172.23.0.5 (executor 0) (158/202)
[2024-11-10T00:03:34.358+0000] {spark_submit.py:634} INFO - 24/11/10 00:03:34 INFO TaskSetManager: Starting task 160.0 in stage 1.0 (TID 161) (172.23.0.5, executor 0, partition 160, PROCESS_LOCAL, 7919 bytes)
[2024-11-10T00:03:34.360+0000] {spark_submit.py:634} INFO - 24/11/10 00:03:34 INFO TaskSetManager: Finished task 158.0 in stage 1.0 (TID 159) in 2392 ms on 172.23.0.5 (executor 0) (159/202)
[2024-11-10T00:03:35.530+0000] {spark_submit.py:634} INFO - 24/11/10 00:03:35 INFO TaskSetManager: Starting task 161.0 in stage 1.0 (TID 162) (172.23.0.5, executor 0, partition 161, PROCESS_LOCAL, 7919 bytes)
[2024-11-10T00:03:35.534+0000] {spark_submit.py:634} INFO - 24/11/10 00:03:35 INFO TaskSetManager: Finished task 159.0 in stage 1.0 (TID 160) in 2393 ms on 172.23.0.5 (executor 0) (160/202)
[2024-11-10T00:03:36.735+0000] {spark_submit.py:634} INFO - 24/11/10 00:03:36 INFO TaskSetManager: Starting task 162.0 in stage 1.0 (TID 163) (172.23.0.5, executor 0, partition 162, PROCESS_LOCAL, 7919 bytes)
[2024-11-10T00:03:36.736+0000] {spark_submit.py:634} INFO - 24/11/10 00:03:36 INFO TaskSetManager: Finished task 160.0 in stage 1.0 (TID 161) in 2377 ms on 172.23.0.5 (executor 0) (161/202)
[2024-11-10T00:03:37.913+0000] {spark_submit.py:634} INFO - 24/11/10 00:03:37 INFO TaskSetManager: Starting task 163.0 in stage 1.0 (TID 164) (172.23.0.5, executor 0, partition 163, PROCESS_LOCAL, 7919 bytes)
[2024-11-10T00:03:37.915+0000] {spark_submit.py:634} INFO - 24/11/10 00:03:37 INFO TaskSetManager: Finished task 161.0 in stage 1.0 (TID 162) in 2384 ms on 172.23.0.5 (executor 0) (162/202)
[2024-11-10T00:03:39.189+0000] {spark_submit.py:634} INFO - 24/11/10 00:03:39 INFO TaskSetManager: Starting task 164.0 in stage 1.0 (TID 165) (172.23.0.5, executor 0, partition 164, PROCESS_LOCAL, 7919 bytes)
[2024-11-10T00:03:39.191+0000] {spark_submit.py:634} INFO - 24/11/10 00:03:39 INFO TaskSetManager: Finished task 162.0 in stage 1.0 (TID 163) in 2456 ms on 172.23.0.5 (executor 0) (163/202)
[2024-11-10T00:03:40.357+0000] {spark_submit.py:634} INFO - 24/11/10 00:03:40 INFO TaskSetManager: Starting task 165.0 in stage 1.0 (TID 166) (172.23.0.5, executor 0, partition 165, PROCESS_LOCAL, 7919 bytes)
[2024-11-10T00:03:40.358+0000] {spark_submit.py:634} INFO - 24/11/10 00:03:40 INFO TaskSetManager: Finished task 163.0 in stage 1.0 (TID 164) in 2444 ms on 172.23.0.5 (executor 0) (164/202)
[2024-11-10T00:03:41.602+0000] {spark_submit.py:634} INFO - 24/11/10 00:03:41 INFO TaskSetManager: Starting task 166.0 in stage 1.0 (TID 167) (172.23.0.5, executor 0, partition 166, PROCESS_LOCAL, 7919 bytes)
[2024-11-10T00:03:41.603+0000] {spark_submit.py:634} INFO - 24/11/10 00:03:41 INFO TaskSetManager: Finished task 164.0 in stage 1.0 (TID 165) in 2413 ms on 172.23.0.5 (executor 0) (165/202)
[2024-11-10T00:03:42.806+0000] {spark_submit.py:634} INFO - 24/11/10 00:03:42 INFO TaskSetManager: Starting task 167.0 in stage 1.0 (TID 168) (172.23.0.5, executor 0, partition 167, PROCESS_LOCAL, 7919 bytes)
[2024-11-10T00:03:42.807+0000] {spark_submit.py:634} INFO - 24/11/10 00:03:42 INFO TaskSetManager: Finished task 165.0 in stage 1.0 (TID 166) in 2450 ms on 172.23.0.5 (executor 0) (166/202)
[2024-11-10T00:03:44.172+0000] {spark_submit.py:634} INFO - 24/11/10 00:03:44 INFO TaskSetManager: Starting task 168.0 in stage 1.0 (TID 169) (172.23.0.5, executor 0, partition 168, PROCESS_LOCAL, 7919 bytes)
[2024-11-10T00:03:44.173+0000] {spark_submit.py:634} INFO - 24/11/10 00:03:44 INFO TaskSetManager: Finished task 166.0 in stage 1.0 (TID 167) in 2571 ms on 172.23.0.5 (executor 0) (167/202)
[2024-11-10T00:03:45.400+0000] {spark_submit.py:634} INFO - 24/11/10 00:03:45 INFO TaskSetManager: Starting task 169.0 in stage 1.0 (TID 170) (172.23.0.5, executor 0, partition 169, PROCESS_LOCAL, 7919 bytes)
[2024-11-10T00:03:45.401+0000] {spark_submit.py:634} INFO - 24/11/10 00:03:45 INFO TaskSetManager: Finished task 167.0 in stage 1.0 (TID 168) in 2595 ms on 172.23.0.5 (executor 0) (168/202)
[2024-11-10T00:03:46.605+0000] {spark_submit.py:634} INFO - 24/11/10 00:03:46 INFO TaskSetManager: Starting task 170.0 in stage 1.0 (TID 171) (172.23.0.5, executor 0, partition 170, PROCESS_LOCAL, 7919 bytes)
[2024-11-10T00:03:46.606+0000] {spark_submit.py:634} INFO - 24/11/10 00:03:46 INFO TaskSetManager: Finished task 168.0 in stage 1.0 (TID 169) in 2434 ms on 172.23.0.5 (executor 0) (169/202)
[2024-11-10T00:03:47.917+0000] {spark_submit.py:634} INFO - 24/11/10 00:03:47 INFO TaskSetManager: Starting task 171.0 in stage 1.0 (TID 172) (172.23.0.5, executor 0, partition 171, PROCESS_LOCAL, 7919 bytes)
[2024-11-10T00:03:47.918+0000] {spark_submit.py:634} INFO - 24/11/10 00:03:47 INFO TaskSetManager: Finished task 169.0 in stage 1.0 (TID 170) in 2518 ms on 172.23.0.5 (executor 0) (170/202)
[2024-11-10T00:03:49.141+0000] {spark_submit.py:634} INFO - 24/11/10 00:03:49 INFO TaskSetManager: Starting task 172.0 in stage 1.0 (TID 173) (172.23.0.5, executor 0, partition 172, PROCESS_LOCAL, 7919 bytes)
[2024-11-10T00:03:49.142+0000] {spark_submit.py:634} INFO - 24/11/10 00:03:49 INFO TaskSetManager: Finished task 170.0 in stage 1.0 (TID 171) in 2537 ms on 172.23.0.5 (executor 0) (171/202)
[2024-11-10T00:03:50.446+0000] {spark_submit.py:634} INFO - 24/11/10 00:03:50 INFO TaskSetManager: Starting task 173.0 in stage 1.0 (TID 174) (172.23.0.5, executor 0, partition 173, PROCESS_LOCAL, 7919 bytes)
[2024-11-10T00:03:50.447+0000] {spark_submit.py:634} INFO - 24/11/10 00:03:50 INFO TaskSetManager: Finished task 171.0 in stage 1.0 (TID 172) in 2530 ms on 172.23.0.5 (executor 0) (172/202)
[2024-11-10T00:03:51.638+0000] {spark_submit.py:634} INFO - 24/11/10 00:03:51 INFO TaskSetManager: Starting task 174.0 in stage 1.0 (TID 175) (172.23.0.5, executor 0, partition 174, PROCESS_LOCAL, 7919 bytes)
[2024-11-10T00:03:51.640+0000] {spark_submit.py:634} INFO - 24/11/10 00:03:51 INFO TaskSetManager: Finished task 172.0 in stage 1.0 (TID 173) in 2499 ms on 172.23.0.5 (executor 0) (173/202)
[2024-11-10T00:03:52.976+0000] {spark_submit.py:634} INFO - 24/11/10 00:03:52 INFO TaskSetManager: Starting task 175.0 in stage 1.0 (TID 176) (172.23.0.5, executor 0, partition 175, PROCESS_LOCAL, 7919 bytes)
[2024-11-10T00:03:52.977+0000] {spark_submit.py:634} INFO - 24/11/10 00:03:52 INFO TaskSetManager: Finished task 173.0 in stage 1.0 (TID 174) in 2530 ms on 172.23.0.5 (executor 0) (174/202)
[2024-11-10T00:03:54.156+0000] {spark_submit.py:634} INFO - 24/11/10 00:03:54 INFO TaskSetManager: Starting task 176.0 in stage 1.0 (TID 177) (172.23.0.5, executor 0, partition 176, PROCESS_LOCAL, 7919 bytes)
[2024-11-10T00:03:54.157+0000] {spark_submit.py:634} INFO - 24/11/10 00:03:54 INFO TaskSetManager: Finished task 174.0 in stage 1.0 (TID 175) in 2518 ms on 172.23.0.5 (executor 0) (175/202)
[2024-11-10T00:03:55.428+0000] {spark_submit.py:634} INFO - 24/11/10 00:03:55 INFO TaskSetManager: Starting task 177.0 in stage 1.0 (TID 178) (172.23.0.5, executor 0, partition 177, PROCESS_LOCAL, 7919 bytes)
[2024-11-10T00:03:55.429+0000] {spark_submit.py:634} INFO - 24/11/10 00:03:55 INFO TaskSetManager: Finished task 175.0 in stage 1.0 (TID 176) in 2453 ms on 172.23.0.5 (executor 0) (176/202)
[2024-11-10T00:03:56.584+0000] {spark_submit.py:634} INFO - 24/11/10 00:03:56 INFO TaskSetManager: Starting task 178.0 in stage 1.0 (TID 179) (172.23.0.5, executor 0, partition 178, PROCESS_LOCAL, 7919 bytes)
[2024-11-10T00:03:56.586+0000] {spark_submit.py:634} INFO - 24/11/10 00:03:56 INFO TaskSetManager: Finished task 176.0 in stage 1.0 (TID 177) in 2428 ms on 172.23.0.5 (executor 0) (177/202)
[2024-11-10T00:03:57.918+0000] {spark_submit.py:634} INFO - 24/11/10 00:03:57 INFO TaskSetManager: Starting task 179.0 in stage 1.0 (TID 180) (172.23.0.5, executor 0, partition 179, PROCESS_LOCAL, 7919 bytes)
[2024-11-10T00:03:57.919+0000] {spark_submit.py:634} INFO - 24/11/10 00:03:57 INFO TaskSetManager: Finished task 177.0 in stage 1.0 (TID 178) in 2491 ms on 172.23.0.5 (executor 0) (178/202)
[2024-11-10T00:03:59.190+0000] {spark_submit.py:634} INFO - 24/11/10 00:03:59 INFO TaskSetManager: Starting task 180.0 in stage 1.0 (TID 181) (172.23.0.5, executor 0, partition 180, PROCESS_LOCAL, 7919 bytes)
[2024-11-10T00:03:59.191+0000] {spark_submit.py:634} INFO - 24/11/10 00:03:59 INFO TaskSetManager: Finished task 178.0 in stage 1.0 (TID 179) in 2606 ms on 172.23.0.5 (executor 0) (179/202)
[2024-11-10T00:04:00.368+0000] {spark_submit.py:634} INFO - 24/11/10 00:04:00 INFO TaskSetManager: Starting task 181.0 in stage 1.0 (TID 182) (172.23.0.5, executor 0, partition 181, PROCESS_LOCAL, 7919 bytes)
[2024-11-10T00:04:00.369+0000] {spark_submit.py:634} INFO - 24/11/10 00:04:00 INFO TaskSetManager: Finished task 179.0 in stage 1.0 (TID 180) in 2451 ms on 172.23.0.5 (executor 0) (180/202)
[2024-11-10T00:04:01.655+0000] {spark_submit.py:634} INFO - 24/11/10 00:04:01 INFO TaskSetManager: Starting task 182.0 in stage 1.0 (TID 183) (172.23.0.5, executor 0, partition 182, PROCESS_LOCAL, 7919 bytes)
[2024-11-10T00:04:01.657+0000] {spark_submit.py:634} INFO - 24/11/10 00:04:01 INFO TaskSetManager: Finished task 180.0 in stage 1.0 (TID 181) in 2466 ms on 172.23.0.5 (executor 0) (181/202)
[2024-11-10T00:04:02.845+0000] {spark_submit.py:634} INFO - 24/11/10 00:04:02 INFO TaskSetManager: Starting task 183.0 in stage 1.0 (TID 184) (172.23.0.5, executor 0, partition 183, PROCESS_LOCAL, 7919 bytes)
[2024-11-10T00:04:02.846+0000] {spark_submit.py:634} INFO - 24/11/10 00:04:02 INFO TaskSetManager: Finished task 181.0 in stage 1.0 (TID 182) in 2478 ms on 172.23.0.5 (executor 0) (182/202)
[2024-11-10T00:04:04.170+0000] {spark_submit.py:634} INFO - 24/11/10 00:04:04 INFO TaskSetManager: Starting task 184.0 in stage 1.0 (TID 185) (172.23.0.5, executor 0, partition 184, PROCESS_LOCAL, 7919 bytes)
[2024-11-10T00:04:04.176+0000] {spark_submit.py:634} INFO - 24/11/10 00:04:04 INFO TaskSetManager: Finished task 182.0 in stage 1.0 (TID 183) in 2515 ms on 172.23.0.5 (executor 0) (183/202)
[2024-11-10T00:04:05.335+0000] {spark_submit.py:634} INFO - 24/11/10 00:04:05 INFO TaskSetManager: Starting task 185.0 in stage 1.0 (TID 186) (172.23.0.5, executor 0, partition 185, PROCESS_LOCAL, 7919 bytes)
[2024-11-10T00:04:05.337+0000] {spark_submit.py:634} INFO - 24/11/10 00:04:05 INFO TaskSetManager: Finished task 183.0 in stage 1.0 (TID 184) in 2490 ms on 172.23.0.5 (executor 0) (184/202)
[2024-11-10T00:04:06.655+0000] {spark_submit.py:634} INFO - 24/11/10 00:04:06 INFO TaskSetManager: Starting task 186.0 in stage 1.0 (TID 187) (172.23.0.5, executor 0, partition 186, PROCESS_LOCAL, 7919 bytes)
[2024-11-10T00:04:06.656+0000] {spark_submit.py:634} INFO - 24/11/10 00:04:06 INFO TaskSetManager: Finished task 184.0 in stage 1.0 (TID 185) in 2485 ms on 172.23.0.5 (executor 0) (185/202)
[2024-11-10T00:04:07.807+0000] {spark_submit.py:634} INFO - 24/11/10 00:04:07 INFO TaskSetManager: Starting task 187.0 in stage 1.0 (TID 188) (172.23.0.5, executor 0, partition 187, PROCESS_LOCAL, 7919 bytes)
[2024-11-10T00:04:07.809+0000] {spark_submit.py:634} INFO - 24/11/10 00:04:07 INFO TaskSetManager: Finished task 185.0 in stage 1.0 (TID 186) in 2473 ms on 172.23.0.5 (executor 0) (186/202)
[2024-11-10T00:04:09.121+0000] {spark_submit.py:634} INFO - 24/11/10 00:04:09 INFO TaskSetManager: Starting task 188.0 in stage 1.0 (TID 189) (172.23.0.5, executor 0, partition 188, PROCESS_LOCAL, 7919 bytes)
[2024-11-10T00:04:09.122+0000] {spark_submit.py:634} INFO - 24/11/10 00:04:09 INFO TaskSetManager: Finished task 186.0 in stage 1.0 (TID 187) in 2467 ms on 172.23.0.5 (executor 0) (187/202)
[2024-11-10T00:04:10.256+0000] {spark_submit.py:634} INFO - 24/11/10 00:04:10 INFO TaskSetManager: Starting task 189.0 in stage 1.0 (TID 190) (172.23.0.5, executor 0, partition 189, PROCESS_LOCAL, 7919 bytes)
[2024-11-10T00:04:10.257+0000] {spark_submit.py:634} INFO - 24/11/10 00:04:10 INFO TaskSetManager: Finished task 187.0 in stage 1.0 (TID 188) in 2449 ms on 172.23.0.5 (executor 0) (188/202)
[2024-11-10T00:04:11.595+0000] {spark_submit.py:634} INFO - 24/11/10 00:04:11 INFO TaskSetManager: Starting task 190.0 in stage 1.0 (TID 191) (172.23.0.5, executor 0, partition 190, PROCESS_LOCAL, 7919 bytes)
[2024-11-10T00:04:11.597+0000] {spark_submit.py:634} INFO - 24/11/10 00:04:11 INFO TaskSetManager: Finished task 188.0 in stage 1.0 (TID 189) in 2475 ms on 172.23.0.5 (executor 0) (189/202)
[2024-11-10T00:04:12.732+0000] {spark_submit.py:634} INFO - 24/11/10 00:04:12 INFO TaskSetManager: Starting task 191.0 in stage 1.0 (TID 192) (172.23.0.5, executor 0, partition 191, PROCESS_LOCAL, 7919 bytes)
[2024-11-10T00:04:12.734+0000] {spark_submit.py:634} INFO - 24/11/10 00:04:12 INFO TaskSetManager: Finished task 189.0 in stage 1.0 (TID 190) in 2478 ms on 172.23.0.5 (executor 0) (190/202)
[2024-11-10T00:04:14.051+0000] {spark_submit.py:634} INFO - 24/11/10 00:04:14 INFO TaskSetManager: Starting task 192.0 in stage 1.0 (TID 193) (172.23.0.5, executor 0, partition 192, PROCESS_LOCAL, 7919 bytes)
[2024-11-10T00:04:14.053+0000] {spark_submit.py:634} INFO - 24/11/10 00:04:14 INFO TaskSetManager: Finished task 190.0 in stage 1.0 (TID 191) in 2456 ms on 172.23.0.5 (executor 0) (191/202)
[2024-11-10T00:04:15.105+0000] {spark_submit.py:634} INFO - 24/11/10 00:04:15 INFO TaskSetManager: Starting task 193.0 in stage 1.0 (TID 194) (172.23.0.5, executor 0, partition 193, PROCESS_LOCAL, 7919 bytes)
[2024-11-10T00:04:15.106+0000] {spark_submit.py:634} INFO - 24/11/10 00:04:15 INFO TaskSetManager: Finished task 191.0 in stage 1.0 (TID 192) in 2373 ms on 172.23.0.5 (executor 0) (192/202)
[2024-11-10T00:04:16.443+0000] {spark_submit.py:634} INFO - 24/11/10 00:04:16 INFO TaskSetManager: Starting task 194.0 in stage 1.0 (TID 195) (172.23.0.5, executor 0, partition 194, PROCESS_LOCAL, 7919 bytes)
[2024-11-10T00:04:16.444+0000] {spark_submit.py:634} INFO - 24/11/10 00:04:16 INFO TaskSetManager: Finished task 192.0 in stage 1.0 (TID 193) in 2393 ms on 172.23.0.5 (executor 0) (193/202)
[2024-11-10T00:04:17.558+0000] {spark_submit.py:634} INFO - 24/11/10 00:04:17 INFO TaskSetManager: Starting task 195.0 in stage 1.0 (TID 196) (172.23.0.5, executor 0, partition 195, PROCESS_LOCAL, 7919 bytes)
[2024-11-10T00:04:17.559+0000] {spark_submit.py:634} INFO - 24/11/10 00:04:17 INFO TaskSetManager: Finished task 193.0 in stage 1.0 (TID 194) in 2454 ms on 172.23.0.5 (executor 0) (194/202)
[2024-11-10T00:04:18.826+0000] {spark_submit.py:634} INFO - 24/11/10 00:04:18 INFO TaskSetManager: Starting task 196.0 in stage 1.0 (TID 197) (172.23.0.5, executor 0, partition 196, PROCESS_LOCAL, 7919 bytes)
[2024-11-10T00:04:18.827+0000] {spark_submit.py:634} INFO - 24/11/10 00:04:18 INFO TaskSetManager: Finished task 194.0 in stage 1.0 (TID 195) in 2384 ms on 172.23.0.5 (executor 0) (195/202)
[2024-11-10T00:04:19.972+0000] {spark_submit.py:634} INFO - 24/11/10 00:04:19 INFO TaskSetManager: Starting task 197.0 in stage 1.0 (TID 198) (172.23.0.5, executor 0, partition 197, PROCESS_LOCAL, 7919 bytes)
[2024-11-10T00:04:19.973+0000] {spark_submit.py:634} INFO - 24/11/10 00:04:19 INFO TaskSetManager: Finished task 195.0 in stage 1.0 (TID 196) in 2415 ms on 172.23.0.5 (executor 0) (196/202)
[2024-11-10T00:04:21.061+0000] {spark_submit.py:634} INFO - 24/11/10 00:04:21 INFO TaskSetManager: Starting task 198.0 in stage 1.0 (TID 199) (172.23.0.5, executor 0, partition 198, PROCESS_LOCAL, 7919 bytes)
[2024-11-10T00:04:21.062+0000] {spark_submit.py:634} INFO - 24/11/10 00:04:21 INFO TaskSetManager: Finished task 196.0 in stage 1.0 (TID 197) in 2236 ms on 172.23.0.5 (executor 0) (197/202)
[2024-11-10T00:04:22.428+0000] {spark_submit.py:634} INFO - 24/11/10 00:04:22 INFO TaskSetManager: Starting task 199.0 in stage 1.0 (TID 200) (172.23.0.5, executor 0, partition 199, PROCESS_LOCAL, 7919 bytes)
[2024-11-10T00:04:22.430+0000] {spark_submit.py:634} INFO - 24/11/10 00:04:22 INFO TaskSetManager: Finished task 197.0 in stage 1.0 (TID 198) in 2457 ms on 172.23.0.5 (executor 0) (198/202)
[2024-11-10T00:04:23.473+0000] {spark_submit.py:634} INFO - 24/11/10 00:04:23 INFO TaskSetManager: Starting task 200.0 in stage 1.0 (TID 201) (172.23.0.5, executor 0, partition 200, PROCESS_LOCAL, 7919 bytes)
[2024-11-10T00:04:23.474+0000] {spark_submit.py:634} INFO - 24/11/10 00:04:23 INFO TaskSetManager: Finished task 198.0 in stage 1.0 (TID 199) in 2412 ms on 172.23.0.5 (executor 0) (199/202)
[2024-11-10T00:04:24.875+0000] {spark_submit.py:634} INFO - 24/11/10 00:04:24 INFO TaskSetManager: Starting task 201.0 in stage 1.0 (TID 202) (172.23.0.5, executor 0, partition 201, PROCESS_LOCAL, 7919 bytes)
[2024-11-10T00:04:24.876+0000] {spark_submit.py:634} INFO - 24/11/10 00:04:24 INFO TaskSetManager: Finished task 199.0 in stage 1.0 (TID 200) in 2448 ms on 172.23.0.5 (executor 0) (200/202)
[2024-11-10T00:04:25.896+0000] {spark_submit.py:634} INFO - 24/11/10 00:04:25 INFO TaskSetManager: Finished task 200.0 in stage 1.0 (TID 201) in 2423 ms on 172.23.0.5 (executor 0) (201/202)
[2024-11-10T00:04:27.070+0000] {spark_submit.py:634} INFO - 24/11/10 00:04:27 INFO TaskSetManager: Finished task 201.0 in stage 1.0 (TID 202) in 2196 ms on 172.23.0.5 (executor 0) (202/202)
[2024-11-10T00:04:27.072+0000] {spark_submit.py:634} INFO - 24/11/10 00:04:27 INFO TaskSchedulerImpl: Removed TaskSet 1.0, whose tasks have all completed, from pool
[2024-11-10T00:04:27.073+0000] {spark_submit.py:634} INFO - 24/11/10 00:04:27 INFO DAGScheduler: ResultStage 1 (csv at NativeMethodAccessorImpl.java:0) finished in 251.325 s
